<sdf version='1.6'>
  <world name='default'>
    <model name='ground_plane'>
      <static>1</static>
      <link name='link'>
        <collision name='collision'>
          <geometry>
            <plane>
              <normal>0 0 1</normal>
              <size>100 100</size>
            </plane>
          </geometry>
          <surface>
            <friction>
              <ode>
                <mu>100</mu>
                <mu2>50</mu2>
              </ode>
              <torsional>
                <ode/>
              </torsional>
            </friction>
            <contact>
              <ode/>
            </contact>
            <bounce/>
          </surface>
          <max_contacts>10</max_contacts>
        </collision>
        <visual name='visual'>
          <cast_shadows>0</cast_shadows>
          <geometry>
            <plane>
              <normal>0 0 1</normal>
              <size>100 100</size>
            </plane>
          </geometry>
          <material>
            <script>
              <uri>file://media/materials/scripts/gazebo.material</uri>
              <name>Gazebo/Grey</name>
            </script>
          </material>
        </visual>
        <self_collide>0</self_collide>
        <enable_wind>0</enable_wind>
        <kinematic>0</kinematic>
      </link>
    </model>
    <light name='sun' type='directional'>
      <cast_shadows>1</cast_shadows>
      <pose frame=''>0 0 10 0 -0 0</pose>
      <diffuse>0.8 0.8 0.8 1</diffuse>
      <specular>0.2 0.2 0.2 1</specular>
      <attenuation>
        <range>1000</range>
        <constant>0.9</constant>
        <linear>0.01</linear>
        <quadratic>0.001</quadratic>
      </attenuation>
      <direction>-0.5 0.1 -0.9</direction>
    </light>
    <gravity>0 0 -9.8</gravity>
    <magnetic_field>6e-06 2.3e-05 -4.2e-05</magnetic_field>
    <atmosphere type='adiabatic'/>
    <physics name='default_physics' default='0' type='ode'>
      <max_step_size>0.001</max_step_size>
      <real_time_factor>1</real_time_factor>
      <real_time_update_rate>1000</real_time_update_rate>
    </physics>
    <scene>
      <ambient>0.4 0.4 0.4 1</ambient>
      <background>0.7 0.7 0.7 1</background>
      <shadows>1</shadows>
    </scene>
    <wind/>
    <spherical_coordinates>
      <surface_model>EARTH_WGS84</surface_model>
      <latitude_deg>0</latitude_deg>
      <longitude_deg>0</longitude_deg>
      <elevation>0</elevation>
      <heading_deg>0</heading_deg>
    </spherical_coordinates>
    <state world_name='default'>
      <sim_time>3172 593000000</sim_time>
      <real_time>2381 477098237</real_time>
      <wall_time>1647914414 893782330</wall_time>
      <iterations>1251572</iterations>
      <model name='ground_plane'>
        <pose frame=''>0 0 0 0 -0 0</pose>
        <scale>1 1 1</scale>
        <link name='link'>
          <pose frame=''>0 0 0 0 -0 0</pose>
          <velocity>0 0 0 0 -0 0</velocity>
          <acceleration>0 0 0 0 -0 0</acceleration>
          <wrench>0 0 0 0 -0 0</wrench>
        </link>
      </model>
      <model name='hsrb'>
        <pose frame=''>1.11572 -4.52555 -0.000108 0.00012 -0.00018 -1.18996</pose>
        <scale>1 1 1</scale>
        <link name='arm_flex_link'>
          <pose frame=''>1.24048 -4.62741 0.339922 0.000138 -0.000269 -1.18995</pose>
          <velocity>0.133025 -0.167566 -0.004075 -0.078058 -0.030779 0.455691</velocity>
          <acceleration>-4.17613 1.82435 -6.5506 2.74885 -1.56418 2.33088</acceleration>
          <wrench>-5.59305 2.44334 -8.77315 0 -0 0</wrench>
        </link>
        <link name='arm_lift_link'>
          <pose frame=''>1.11566 -4.5255 0.33989 0.000153 -0.000165 -1.18995</pose>
          <velocity>0.086993 -0.224309 -0.00103 0.020495 0.012263 0.455519</velocity>
          <acceleration>0.50063 -4.25775 -4.28749 1.05631 0.331729 2.1368</acceleration>
          <wrench>0.638714 -5.43212 -5.47006 0 -0 0</wrench>
        </link>
        <link name='arm_roll_link'>
          <pose frame=''>1.24226 -4.63198 0.684921 0.000137 -0.000275 -1.19502</pose>
          <velocity>0.124549 -0.140087 -0.003353 -0.074419 -0.028824 0.487064</velocity>
          <acceleration>-8.8891 14.61 -6.12702 0.921822 1.13039 1.67407</acceleration>
          <wrench>-2.20393 3.62234 -1.51911 0 -0 0</wrench>
        </link>
        <link name='base_b_bumper_link'>
          <pose frame=''>1.11692 -4.52506 -0.000108 -0.00012 0.000181 1.95164</pose>
          <velocity>0.084193 -0.215508 -0.001517 0.025711 0.006306 0.458048</velocity>
          <acceleration>-1.18175 7.71874 -3.00713 2.87711 1.45496 0.765984</acceleration>
          <wrench>-0.070905 0.463124 -0.180428 0 -0 0</wrench>
        </link>
        <link name='base_f_bumper_link'>
          <pose frame=''>1.11572 -4.52555 -0.000108 0.00012 -0.000181 -1.18996</pose>
          <velocity>0.084414 -0.21606 -0.001522 0.025717 0.006301 0.458049</velocity>
          <acceleration>-1.1902 7.74216 -3.01702 -0.410787 1.3019 -2.37148</acceleration>
          <wrench>-0.071412 0.46453 -0.181021 0 -0 0</wrench>
        </link>
        <link name='base_footprint'>
          <pose frame=''>1.11572 -4.52555 -0.000108 0.00012 -0.00018 -1.18996</pose>
          <velocity>0.084408 -0.216107 -0.001499 0.025369 0.006512 0.458091</velocity>
          <acceleration>0.649374 0.877816 -1.97051 -1.59426 -0.501612 2.81351</acceleration>
          <wrench>32.4817 43.9084 -98.5649 0 -0 0</wrench>
        </link>
        <link name='base_l_drive_wheel_link'>
          <pose frame=''>1.22174 -4.3893 0.039892 3.14112 1.20635 1.78876</pose>
          <velocity>0.039543 -0.178474 0.001773 -1.84546 0.983251 0.33968</velocity>
          <acceleration>-3.45509 15.1769 2.62663 1.61335 1.09716 -0.382807</acceleration>
          <wrench>-0.691018 3.03539 0.525327 0 -0 0</wrench>
        </link>
        <link name='base_l_passive_wheel_x_frame'>
          <pose frame=''>1.2018 -4.65957 0.02995 -0.323227 -0.000179 -1.35235</pose>
          <velocity>0.130796 -0.187681 -0.012066 -0.05367 0.385999 0.339096</velocity>
          <acceleration>4.70455 9.16429 -22.255 -1.00616 -1.0241 0.019568</acceleration>
          <wrench>0.94091 1.83286 -4.451 0 -0 0</wrench>
        </link>
        <link name='base_l_passive_wheel_y_frame'>
          <pose frame=''>1.2018 -4.65957 0.029967 -2.80864 0.238032 1.87055</pose>
          <velocity>0.131201 -0.18728 -0.016137 -1.0898 0.89569 0.604632</velocity>
          <acceleration>5.51478 9.96739 -30.4011 -0.469005 -0.628273 2.93894</acceleration>
          <wrench>1.10295 1.99348 -6.08021 0 -0 0</wrench>
        </link>
        <link name='base_l_passive_wheel_z_link'>
          <pose frame=''>1.2018 -4.65957 0.029983 2.73974 -0.064643 -0.82355</pose>
          <velocity>0.131619 -0.186838 -0.020188 -0.514551 0.160303 2.75705</velocity>
          <acceleration>6.36762 10.8651 -38.5039 -0.204937 -0.405249 -2.21415</acceleration>
          <wrench>1.27352 2.17302 -7.70078 0 -0 0</wrench>
        </link>
        <link name='base_r_drive_wheel_link'>
          <pose frame=''>0.962045 -4.44701 0.039855 3.14142 -0.542731 1.78929</pose>
          <velocity>0.059511 -0.268584 0.001697 0.407388 1.48245 0.339758</velocity>
          <acceleration>-0.754022 2.95665 1.87594 -0.705467 -0.480003 -0.78986</acceleration>
          <wrench>-0.150804 0.591331 0.375187 0 -0 0</wrench>
        </link>
        <link name='base_r_passive_wheel_x_frame'>
          <pose frame=''>1.09441 -4.6834 0.029939 0.967344 -0.000164 -1.35236</pose>
          <velocity>0.138978 -0.225634 -0.01308 -0.136031 0.742959 0.339613</velocity>
          <acceleration>5.68559 2.72735 -24.5051 2.51927 0.917484 1.25247</acceleration>
          <wrench>1.13712 0.545469 -4.90102 0 -0 0</wrench>
        </link>
        <link name='base_r_passive_wheel_y_frame'>
          <pose frame=''>1.09441 -4.6834 0.02996 1.39874 -0.581363 -2.61653</pose>
          <velocity>0.1395 -0.226165 -0.01833 -2.91404 -1.17532 -2.10202</velocity>
          <acceleration>6.72965 1.66747 -34.9954 -1.40998 -0.233809 -0.141876</acceleration>
          <wrench>1.34593 0.333493 -6.99909 0 -0 0</wrench>
        </link>
        <link name='base_r_passive_wheel_z_link'>
          <pose frame=''>1.09441 -4.6834 0.02998 -1.285 -1.03803 0.181933</pose>
          <velocity>0.140038 -0.226654 -0.023563 -1.87705 1.03523 -2.47005</velocity>
          <acceleration>7.82546 0.671838 -45.4481 1.55807 -0.853331 0.668852</acceleration>
          <wrench>1.56509 0.134368 -9.08962 0 -0 0</wrench>
        </link>
        <link name='base_roll_link'>
          <pose frame=''>1.11572 -4.52555 -0.000107 0.000148 -0.000178 -1.35235</pose>
          <velocity>0.084547 -0.216295 -0.001736 0.030586 0.006756 0.339446</velocity>
          <acceleration>-0.930244 3.63368 -2.44471 -0.210733 -0.717958 0.431767</acceleration>
          <wrench>-9.52514 37.2067 -25.0324 0 -0 0</wrench>
        </link>
        <link name='hand_l_distal_link'>
          <pose frame=''>1.27266 -4.64978 0.877962 0.025204 0.007349 1.93047</pose>
          <velocity>0.082916 -0.161073 -0.004917 -0.014462 -0.008565 0.498096</velocity>
          <acceleration>78.2146 -164.576 -5.11355 0.982265 -0.591523 -1.39364</acceleration>
          <wrench>3.73326 -7.85536 -0.244075 0 -0 0</wrench>
        </link>
        <link name='hand_l_mimic_distal_link'>
          <pose frame=''>1.27266 -4.64978 0.877961 -0.046789 0.007354 1.93045</pose>
          <velocity>0.083238 -0.160929 -0.004699 -0.017037 -0.002433 0.497907</velocity>
          <acceleration>83.238 -160.929 -4.69908 -1.32951 -0.70873 -1.60643</acceleration>
          <wrench>0.83238 -1.60929 -0.046991 0 -0 0</wrench>
        </link>
        <link name='hand_l_proximal_link'>
          <pose frame=''>1.27526 -4.6493 0.808024 -0.044982 0.005078 1.94163</pose>
          <velocity>0.142985 -0.136245 -0.00115 0.02427 0.100303 0.471569</velocity>
          <acceleration>6.06355 13.6951 0.028608 -0.269331 -1.13189 1.87962</acceleration>
          <wrench>0.060635 0.136951 0.000286 0 -0 0</wrench>
        </link>
        <link name='hand_l_spring_proximal_link'>
          <pose frame=''>1.27526 -4.6493 0.808023 -0.0445 0.005902 1.92566</pose>
          <velocity>0.144086 -0.135425 -0.000873 0.344916 -0.964492 0.447818</velocity>
          <acceleration>-30.0338 2.00886 -6.62629 -0.601339 0.116811 -1.24695</acceleration>
          <wrench>-1.30914 0.087564 -0.288833 0 -0 0</wrench>
        </link>
        <link name='hand_motor_dummy_link'>
          <pose frame=''>1.24633 -4.64249 0.825447 -0.045064 0.005059 1.94169</pose>
          <velocity>0.138649 -0.151189 -0.000889 0.05501 0.023956 0.472508</velocity>
          <acceleration>138.649 -151.189 -0.888506 -1.53883 -1.17662 1.26936</acceleration>
          <wrench>1.38649 -1.51189 -0.008885 0 -0 0</wrench>
        </link>
        <link name='hand_r_distal_link'>
          <pose frame=''>1.22309 -4.66908 0.877691 -0.050121 0.007371 1.93552</pose>
          <velocity>0.121713 -0.176099 -0.005331 0.011646 -0.0168 0.477934</velocity>
          <acceleration>112.711 -174.334 -5.04992 2.74356 -0.201128 -2.68021</acceleration>
          <wrench>3.48582 -5.39162 -0.156179 0 -0 0</wrench>
        </link>
        <link name='hand_r_mimic_distal_link'>
          <pose frame=''>1.22309 -4.66908 0.877691 -0.100691 0.007375 1.93551</pose>
          <velocity>0.121835 -0.176144 -0.005276 -0.102785 0.282488 0.475483</velocity>
          <acceleration>121.835 -176.144 -5.27572 -2.25368 -0.25515 -2.03942</acceleration>
          <wrench>1.21835 -1.76144 -0.052757 0 -0 0</wrench>
        </link>
        <link name='hand_r_proximal_link'>
          <pose frame=''>1.2296 -4.66706 0.808028 -0.049371 0.005072 1.94166</pose>
          <velocity>0.150341 -0.158588 -0.001257 0.104836 -0.106504 0.472977</velocity>
          <acceleration>3.8101 11.9339 -0.051284 0.265779 1.04303 1.04638</acceleration>
          <wrench>0.038101 0.119339 -0.000513 0 -0 0</wrench>
        </link>
        <link name='hand_r_spring_proximal_link'>
          <pose frame=''>1.22961 -4.66706 0.808029 -0.099369 0.005797 1.93258</pose>
          <velocity>0.150592 -0.158402 -0.001166 0.176532 -0.459867 0.461601</velocity>
          <acceleration>-31.6135 -0.700142 -7.60051 -2.65873 -0.962478 -1.43407</acceleration>
          <wrench>-1.3896 -0.030775 -0.334088 0 -0 0</wrench>
        </link>
        <link name='head_pan_link'>
          <pose frame=''>1.11559 -4.52546 0.751892 0.00012 -0.000172 -1.18995</pose>
          <velocity>0.088941 -0.234463 -0.001358 0.024504 0.005153 0.469801</velocity>
          <acceleration>4.14557 -19.6393 -2.77709 2.54516 -1.04847 -2.14445</acceleration>
          <wrench>2.37086 -11.2318 -1.58822 0 -0 0</wrench>
        </link>
        <link name='head_tilt_link'>
          <pose frame=''>1.12302 -4.54403 0.751892 0.000111 -0.002104 -1.18996</pose>
          <velocity>0.097657 -0.230108 -0.0012 -0.060396 -0.017615 0.470559</velocity>
          <acceleration>1.61582 -8.36913 -7.25052 -1.31749 -0.336227 1.05315</acceleration>
          <wrench>3.56094 -18.4439 -15.9787 0 -0 0</wrench>
        </link>
        <link name='torso_lift_link'>
          <pose frame=''>1.11559 -4.52546 0.751892 0.00012 -0.000175 -1.18996</pose>
          <velocity>0.089184 -0.234576 -0.001446 0.024142 0.006363 0.458362</velocity>
          <acceleration>3.35758 -9.8396 -0.920765 0.238293 0.90873 0.937578</acceleration>
          <wrench>11.4855 -33.6591 -3.14973 0 -0 0</wrench>
        </link>
        <link name='wrist_flex_link'>
          <pose frame=''>1.24226 -4.63198 0.684921 -3.9e-05 -0.005067 -1.195</pose>
          <velocity>0.124505 -0.14021 -0.003402 0.044167 0.039005 0.479922</velocity>
          <acceleration>-10.581 19.7042 -5.41518 -1.48652 0.059995 -0.947218</acceleration>
          <wrench>-7.20804 13.423 -3.68896 0 -0 0</wrench>
        </link>
        <link name='wrist_ft_sensor_frame'>
          <pose frame=''>1.24211 -4.63162 0.758387 -3.14158 -0.005059 -1.19991</pose>
          <velocity>0.131286 -0.149773 -0.000164 0.051006 0.033702 0.472434</velocity>
          <acceleration>1.37667 13.4704 0.606765 2.01544 0.432118 -0.405687</acceleration>
          <wrench>1.29639 12.685 0.571385 0 -0 0</wrench>
        </link>
        <link name='wrist_ft_sensor_mount_link'>
          <pose frame=''>1.24224 -4.63196 0.684874 6e-06 -0.005052 -1.1999</pose>
          <velocity>0.13041 -0.148156 0.001135 0.04803 0.036221 0.472439</velocity>
          <acceleration>-0.750554 16.8545 3.07083 2.61069 -0.751389 2.70201</acceleration>
          <wrench>-0.007506 0.168545 0.030708 0 -0 0</wrench>
        </link>
      </model>
      <model name='iss'>
        <pose frame=''>-0.34103 2.10464 4.6 3.14 -0 3.14</pose>
        <scale>1 1 1</scale>
        <link name='body'>
          <pose frame=''>-0.34103 2.10464 4.6 3.14 -0 3.14</pose>
          <velocity>0 0 0 0 -0 0</velocity>
          <acceleration>0 0 0 0 -0 0</acceleration>
          <wrench>0 0 0 0 -0 0</wrench>
        </link>
      </model>
      <model name='mars_rover'>
        <pose frame=''>-0.820999 -0.667492 0 0 -0 0</pose>
        <scale>1 1 1</scale>
        <link name='link'>
          <pose frame=''>-0.820999 -0.667492 0 0 -0 0</pose>
          <velocity>0 0 0 0 -0 0</velocity>
          <acceleration>0 0 0 0 -0 0</acceleration>
          <wrench>0 0 0 0 -0 0</wrench>
        </link>
      </model>
      <model name='moon_wall'>
        <pose frame=''>4.82024 -9.04733 0 0 0 -0.363517</pose>
        <scale>1 1 1</scale>
        <link name='link'>
          <pose frame=''>4.82024 -9.04733 0 0 0 -0.363517</pose>
          <velocity>0 0 0 0 -0 0</velocity>
          <acceleration>0 0 0 0 -0 0</acceleration>
          <wrench>0 0 0 0 -0 0</wrench>
        </link>
      </model>
      <model name='moon_wall_0'>
        <pose frame=''>8.58004 -1.44362 0 0 0 -0.620662</pose>
        <scale>1 1 1</scale>
        <link name='link'>
          <pose frame=''>8.58004 -1.44362 0 0 0 -0.620662</pose>
          <velocity>0 0 0 0 -0 0</velocity>
          <acceleration>0 0 0 0 -0 0</acceleration>
          <wrench>0 0 0 0 -0 0</wrench>
        </link>
      </model>
      <model name='unit_box'>
        <pose frame=''>-8.86355 -8.91095 0.499995 0 1e-05 0</pose>
        <scale>1 1 1</scale>
        <link name='link'>
          <pose frame=''>-8.86355 -8.91095 0.499995 0 1e-05 0</pose>
          <velocity>0 0 0 0 -0 0</velocity>
          <acceleration>0.010615 -0.006191 -9.78231 0.012424 0.021225 1.8e-05</acceleration>
          <wrench>0.010615 -0.006191 -9.78231 0 -0 0</wrench>
        </link>
      </model>
      <model name='unit_box_0'>
        <pose frame=''>-8.76534 -7.41362 0.499995 1e-05 -0 0</pose>
        <scale>1 1 1</scale>
        <link name='link'>
          <pose frame=''>-8.76534 -7.41362 0.499995 1e-05 -0 0</pose>
          <velocity>0 0 0 0 -0 0</velocity>
          <acceleration>-0.004709 -0.011055 -9.78158 0.022108 -0.009414 1e-06</acceleration>
          <wrench>-0.004709 -0.011055 -9.78158 0 -0 0</wrench>
        </link>
      </model>
      <model name='unit_box_1'>
        <pose frame=''>2.05665 -14.6706 0.5 0 -0 0</pose>
        <scale>1 1 1</scale>
        <link name='link'>
          <pose frame=''>2.05665 -14.6706 0.5 0 -0 0</pose>
          <velocity>0 0 0 0 -0 0</velocity>
          <acceleration>-0.004709 -9.78112 9.78158 0.712677 -0.009414 -4.3e-05</acceleration>
          <wrench>-0.004709 -9.78112 9.78158 0 -0 0</wrench>
        </link>
      </model>
      <model name='unit_box_2'>
        <pose frame=''>-0.068796 -10.6758 0.024569 7e-06 -1e-06 0.918678</pose>
        <scale>4.29908 3.31865 4.5111</scale>
        <link name='link'>
          <pose frame=''>-0.068796 -10.6758 0.024569 7e-06 -1e-06 0.918678</pose>
          <velocity>0 0 0 0 -0 0</velocity>
          <acceleration>0.027625 -0.068911 -0.235964 2.80476 1.12438 0</acceleration>
          <wrench>0.027625 -0.068911 -0.235964 0 -0 0</wrench>
        </link>
      </model>
      <model name='unit_box_clone_0'>
        <pose frame=''>9.45224 -0.370714 0.499986 3e-06 -2e-06 1.11344</pose>
        <scale>12.0836 5.71786 1</scale>
        <link name='link'>
          <pose frame=''>9.45224 -0.370714 0.499986 3e-06 -2e-06 1.11344</pose>
          <velocity>0 0 0 0 -0 0</velocity>
          <acceleration>-0.067253 -0.10713 -9.67742 0.054585 -1.57064 3.12595</acceleration>
          <wrench>-0.067253 -0.10713 -9.67742 0 -0 0</wrench>
        </link>
      </model>
      <model name='unit_box_clone_0_clone'>
        <pose frame=''>5.327 -8.79132 0.499983 2e-06 -3e-06 1.10939</pose>
        <scale>1 1 1</scale>
        <link name='link'>
          <pose frame=''>5.327 -8.79132 0.499983 2e-06 -3e-06 1.10939</pose>
          <velocity>0 0 0 0 -0 0</velocity>
          <acceleration>-0.063129 -0.127062 -9.68839 0.226032 -1.48345 -3.04767</acceleration>
          <wrench>-0.063129 -0.127062 -9.68839 0 -0 0</wrench>
        </link>
      </model>
      <model name='unit_box_clone_0_clone_0'>
        <pose frame=''>-4.41291 -12.5231 0.499787 1.7e-05 -3.5e-05 -0.353427</pose>
        <scale>1 1 1</scale>
        <link name='link'>
          <pose frame=''>-4.41291 -12.5231 0.499787 1.7e-05 -3.5e-05 -0.353427</pose>
          <velocity>0 0 0 0 -0 0</velocity>
          <acceleration>-0.625687 0.227355 -9.17431 -0.934197 -0.534295 -0.172809</acceleration>
          <wrench>-0.625687 0.227355 -9.17431 0 -0 0</wrench>
        </link>
      </model>
      <model name='unit_box_clone_0_clone_0_clone'>
        <pose frame=''>-11.4538 -14.1013 0.499979 -1e-06 -8e-06 -0.354426</pose>
        <scale>1 1 1</scale>
        <link name='link'>
          <pose frame=''>-11.4538 -14.1013 0.499979 -1e-06 -8e-06 -0.354426</pose>
          <velocity>0 0 0 0 -0 0</velocity>
          <acceleration>-2.37641 0.107002 26.991 -0.38732 -0.838135 2.82621</acceleration>
          <wrench>-2.37641 0.107002 26.991 0 -0 0</wrench>
        </link>
      </model>
      <model name='unit_box_clone_0_clone_0_clone_0'>
        <pose frame=''>-3.67903 -3.72525 0.499988 3e-06 -5e-06 -0.353454</pose>
        <scale>1 1 1</scale>
        <link name='link'>
          <pose frame=''>-3.67903 -3.72525 0.499988 3e-06 -5e-06 -0.353454</pose>
          <velocity>0 0 0 0 -0 0</velocity>
          <acceleration>-2.24943 -0.144806 13.9183 -2.58704 -0.00023 -3.10752</acceleration>
          <wrench>-2.24943 -0.144806 13.9183 0 -0 0</wrench>
        </link>
      </model>
      <model name='unit_box_clone_0_clone_1'>
        <pose frame=''>-13.9227 -5.66881 0.499994 2e-06 -2e-06 1.15651</pose>
        <scale>1 1 1</scale>
        <link name='link'>
          <pose frame=''>-13.9227 -5.66881 0.499994 2e-06 -2e-06 1.15651</pose>
          <velocity>0 0 0 0 -0 0</velocity>
          <acceleration>-0.104631 -1.05336 9.744 1.15611 1.38528 3.02476</acceleration>
          <wrench>-0.104631 -1.05336 9.744 0 -0 0</wrench>
        </link>
      </model>
      <model name='unit_box_clone_0_clone_2'>
        <pose frame=''>-9.2739 5.03383 0.499967 -7e-06 5e-06 1.16016</pose>
        <scale>1 1 1</scale>
        <link name='link'>
          <pose frame=''>-9.2739 5.03383 0.499967 -7e-06 5e-06 1.16016</pose>
          <velocity>0 0 0 0 -0 0</velocity>
          <acceleration>0.171558 0.37972 -9.55074 2.2926 0.018855 -2.96225</acceleration>
          <wrench>0.171558 0.37972 -9.55074 0 -0 0</wrench>
        </link>
      </model>
      <model name='unit_box_clone_0_clone_3'>
        <pose frame=''>-1.25433 12.5205 0.499964 0 -1.5e-05 0.327299</pose>
        <scale>1 1 1</scale>
        <link name='link'>
          <pose frame=''>-1.25433 12.5205 0.499964 0 -1.5e-05 0.327299</pose>
          <velocity>0 0 0 0 -0 0</velocity>
          <acceleration>-2.5941 -0.14543 40.5751 1.91485 -1.29133 0.429437</acceleration>
          <wrench>-2.5941 -0.14543 40.5751 0 -0 0</wrench>
        </link>
      </model>
      <model name='unit_box_clone_0_clone_4'>
        <pose frame=''>8.40422 9.72969 0.499989 3e-06 -4e-06 2.24557</pose>
        <scale>1 1 1</scale>
        <link name='link'>
          <pose frame=''>8.40422 9.72969 0.499989 3e-06 -4e-06 2.24557</pose>
          <velocity>0 0 0 0 -0 0</velocity>
          <acceleration>-0.071817 -0.581765 16.6386 1.1682 -0.068365 -3.11939</acceleration>
          <wrench>-0.071817 -0.581765 16.6386 0 -0 0</wrench>
        </link>
      </model>
      <model name='unit_cylinder'>
        <pose frame=''>-3.59772 -15.5649 0.499997 3e-06 3e-06 0</pose>
        <scale>1 1 1</scale>
        <link name='link'>
          <pose frame=''>-3.59772 -15.5649 0.499997 3e-06 3e-06 0</pose>
          <velocity>0 0 0 0 -0 0</velocity>
          <acceleration>0 0 -9.8 0 -0 0</acceleration>
          <wrench>0 0 -9.8 0 -0 0</wrench>
        </link>
      </model>
      <light name='sun'>
        <pose frame=''>0 0 10 0 -0 0</pose>
      </light>
    </state>
    <gui fullscreen='0'>
      <camera name='user_camera'>
        <pose frame=''>-7.91222 -2.17972 22.8889 0 1.15438 -0.074976</pose>
        <view_controller>orbit</view_controller>
        <projection_type>perspective</projection_type>
      </camera>
    </gui>
    <model name='moon_wall'>
      <static>1</static>
      <link name='link'>
        <visual name='visual'>
          <geometry>
            <mesh>
              <uri>model://moon_wall/meshes/moon_wall.dae</uri>
            </mesh>
          </geometry>
        </visual>
        <self_collide>0</self_collide>
        <enable_wind>0</enable_wind>
        <kinematic>0</kinematic>
      </link>
      <pose frame=''>-0.100038 -5.91614 0 0 -0 0</pose>
    </model>
    <model name='moon_wall_0'>
      <static>1</static>
      <link name='link'>
        <visual name='visual'>
          <geometry>
            <mesh>
              <uri>model://moon_wall/meshes/moon_wall.dae</uri>
            </mesh>
          </geometry>
        </visual>
        <self_collide>0</self_collide>
        <enable_wind>0</enable_wind>
        <kinematic>0</kinematic>
      </link>
      <pose frame=''>3.76895 3.71993 0 0 -0 0</pose>
    </model>
    <model name='unit_box_clone_0'>
      <pose frame=''>-9.67451 -0.490249 0.499995 -1e-05 -0 -0</pose>
      <link name='link'>
        <inertial>
          <mass>1</mass>
          <inertia>
            <ixx>0.166667</ixx>
            <ixy>0</ixy>
            <ixz>0</ixz>
            <iyy>0.166667</iyy>
            <iyz>0</iyz>
            <izz>0.166667</izz>
          </inertia>
          <pose frame=''>0 0 0 0 -0 0</pose>
        </inertial>
        <collision name='collision'>
          <geometry>
            <box>
              <size>1 0.005349 1</size>
            </box>
          </geometry>
          <max_contacts>10</max_contacts>
          <surface>
            <contact>
              <ode/>
            </contact>
            <bounce/>
            <friction>
              <torsional>
                <ode/>
              </torsional>
              <ode/>
            </friction>
          </surface>
        </collision>
        <visual name='visual'>
          <geometry>
            <box>
              <size>1 0.005349 1</size>
            </box>
          </geometry>
          <material>
            <script>
              <name>Gazebo/Grey</name>
              <uri>file://media/materials/scripts/gazebo.material</uri>
            </script>
          </material>
        </visual>
        <self_collide>0</self_collide>
        <enable_wind>0</enable_wind>
        <kinematic>0</kinematic>
      </link>
    </model>
    <model name='unit_box_2'>
      <pose frame=''>-0.58082 -9.67836 0.5 0 -0 0</pose>
      <link name='link'>
        <inertial>
          <mass>1</mass>
          <inertia>
            <ixx>0.166667</ixx>
            <ixy>0</ixy>
            <ixz>0</ixz>
            <iyy>0.166667</iyy>
            <iyz>0</iyz>
            <izz>0.166667</izz>
          </inertia>
          <pose frame=''>0 0 0 0 -0 0</pose>
        </inertial>
        <collision name='collision'>
          <geometry>
            <box>
              <size>0.012586 0.02736 0.010893</size>
            </box>
          </geometry>
          <max_contacts>10</max_contacts>
          <surface>
            <contact>
              <ode/>
            </contact>
            <bounce/>
            <friction>
              <torsional>
                <ode/>
              </torsional>
              <ode/>
            </friction>
          </surface>
        </collision>
        <visual name='visual'>
          <geometry>
            <box>
              <size>0.012586 0.02736 0.010893</size>
            </box>
          </geometry>
          <material>
            <script>
              <name>Gazebo/Grey</name>
              <uri>file://media/materials/scripts/gazebo.material</uri>
            </script>
          </material>
        </visual>
        <self_collide>0</self_collide>
        <enable_wind>0</enable_wind>
        <kinematic>0</kinematic>
      </link>
    </model>
    <model name='mars_rover'>
      <static>1</static>
      <link name='link'>
        <collision name='solar_panel_collision'>
          <pose frame=''>0 -0.06945 0.47293 0 -0 0</pose>
          <geometry>
            <box>
              <size>0.87974 0.8821 0.02602</size>
            </box>
          </geometry>
          <max_contacts>10</max_contacts>
          <surface>
            <contact>
              <ode/>
            </contact>
            <bounce/>
            <friction>
              <torsional>
                <ode/>
              </torsional>
              <ode/>
            </friction>
          </surface>
        </collision>
        <collision name='chassis_collision'>
          <pose frame=''>0 -0.05 0.31475 0 -0 0</pose>
          <geometry>
            <box>
              <size>0.49522 0.67401 0.28915</size>
            </box>
          </geometry>
          <max_contacts>10</max_contacts>
          <surface>
            <contact>
              <ode/>
            </contact>
            <bounce/>
            <friction>
              <torsional>
                <ode/>
              </torsional>
              <ode/>
            </friction>
          </surface>
        </collision>
        <collision name='rear_left_bumper_collision'>
          <pose frame=''>0.30107 0.3835 0.38976 0 -0 0</pose>
          <geometry>
            <box>
              <size>0.04442 0.38897 0.07918</size>
            </box>
          </geometry>
          <max_contacts>10</max_contacts>
          <surface>
            <contact>
              <ode/>
            </contact>
            <bounce/>
            <friction>
              <torsional>
                <ode/>
              </torsional>
              <ode/>
            </friction>
          </surface>
        </collision>
        <collision name='rear_right_bumper_collision'>
          <pose frame=''>-0.30107 0.3835 0.38976 0 -0 0</pose>
          <geometry>
            <box>
              <size>0.04442 0.38897 0.07918</size>
            </box>
          </geometry>
          <max_contacts>10</max_contacts>
          <surface>
            <contact>
              <ode/>
            </contact>
            <bounce/>
            <friction>
              <torsional>
                <ode/>
              </torsional>
              <ode/>
            </friction>
          </surface>
        </collision>
        <collision name='rear_bumper_collision'>
          <pose frame=''>0 0.59414 0.38976 0 -0 0</pose>
          <geometry>
            <box>
              <size>0.56656 0.04442 0.07918</size>
            </box>
          </geometry>
          <max_contacts>10</max_contacts>
          <surface>
            <contact>
              <ode/>
            </contact>
            <bounce/>
            <friction>
              <torsional>
                <ode/>
              </torsional>
              <ode/>
            </friction>
          </surface>
        </collision>
        <collision name='bin_back_panel_collision'>
          <pose frame=''>0 0.47 0.32114 0.69137 -0 0</pose>
          <geometry>
            <box>
              <size>0.43774 0.212366 0.05173</size>
            </box>
          </geometry>
          <max_contacts>10</max_contacts>
          <surface>
            <contact>
              <ode/>
            </contact>
            <bounce/>
            <friction>
              <torsional>
                <ode/>
              </torsional>
              <ode/>
            </friction>
          </surface>
        </collision>
        <collision name='bin_left_panel_collision1'>
          <pose frame=''>0.22615 0.32897 0.33193 0 -0 0</pose>
          <geometry>
            <box>
              <size>0.01116 0.19338 0.16304</size>
            </box>
          </geometry>
          <max_contacts>10</max_contacts>
          <surface>
            <contact>
              <ode/>
            </contact>
            <bounce/>
            <friction>
              <torsional>
                <ode/>
              </torsional>
              <ode/>
            </friction>
          </surface>
        </collision>
        <collision name='bin_left_panel_collision2'>
          <pose frame=''>0.22615 0.471 0.39308 0 -0 0</pose>
          <geometry>
            <box>
              <size>0.01116 0.15 0.04</size>
            </box>
          </geometry>
          <max_contacts>10</max_contacts>
          <surface>
            <contact>
              <ode/>
            </contact>
            <bounce/>
            <friction>
              <torsional>
                <ode/>
              </torsional>
              <ode/>
            </friction>
          </surface>
        </collision>
        <collision name='bin_left_panel_collision3'>
          <pose frame=''>0.22615 0.45 0.35308 0 -0 0</pose>
          <geometry>
            <box>
              <size>0.01116 0.15 0.04</size>
            </box>
          </geometry>
          <max_contacts>10</max_contacts>
          <surface>
            <contact>
              <ode/>
            </contact>
            <bounce/>
            <friction>
              <torsional>
                <ode/>
              </torsional>
              <ode/>
            </friction>
          </surface>
        </collision>
        <collision name='bin_left_panel_collision4'>
          <pose frame=''>0.22615 0.39308 0.31308 0 -0 0</pose>
          <geometry>
            <box>
              <size>0.01116 0.15 0.04</size>
            </box>
          </geometry>
          <max_contacts>10</max_contacts>
          <surface>
            <contact>
              <ode/>
            </contact>
            <bounce/>
            <friction>
              <torsional>
                <ode/>
              </torsional>
              <ode/>
            </friction>
          </surface>
        </collision>
        <collision name='bin_right_panel_collision1'>
          <pose frame=''>-0.22615 0.32897 0.33193 0 -0 0</pose>
          <geometry>
            <box>
              <size>0.01116 0.19338 0.16304</size>
            </box>
          </geometry>
          <max_contacts>10</max_contacts>
          <surface>
            <contact>
              <ode/>
            </contact>
            <bounce/>
            <friction>
              <torsional>
                <ode/>
              </torsional>
              <ode/>
            </friction>
          </surface>
        </collision>
        <collision name='bin_right_panel_collision2'>
          <pose frame=''>-0.22615 0.471 0.39308 0 -0 0</pose>
          <geometry>
            <box>
              <size>0.01116 0.15 0.04</size>
            </box>
          </geometry>
          <max_contacts>10</max_contacts>
          <surface>
            <contact>
              <ode/>
            </contact>
            <bounce/>
            <friction>
              <torsional>
                <ode/>
              </torsional>
              <ode/>
            </friction>
          </surface>
        </collision>
        <collision name='bin_right_panel_collision3'>
          <pose frame=''>-0.22615 0.45 0.35308 0 -0 0</pose>
          <geometry>
            <box>
              <size>0.01116 0.15 0.04</size>
            </box>
          </geometry>
          <max_contacts>10</max_contacts>
          <surface>
            <contact>
              <ode/>
            </contact>
            <bounce/>
            <friction>
              <torsional>
                <ode/>
              </torsional>
              <ode/>
            </friction>
          </surface>
        </collision>
        <collision name='bin_right_panel_collision4'>
          <pose frame=''>-0.22615 0.39308 0.31308 0 -0 0</pose>
          <geometry>
            <box>
              <size>0.01116 0.15 0.04</size>
            </box>
          </geometry>
          <max_contacts>10</max_contacts>
          <surface>
            <contact>
              <ode/>
            </contact>
            <bounce/>
            <friction>
              <torsional>
                <ode/>
              </torsional>
              <ode/>
            </friction>
          </surface>
        </collision>
        <collision name='bin_front_panel_collision'>
          <pose frame=''>0 0.30047 0.32114 2.26207 -0 0</pose>
          <geometry>
            <box>
              <size>0.43774 0.212366 0.05173</size>
            </box>
          </geometry>
          <max_contacts>10</max_contacts>
          <surface>
            <contact>
              <ode/>
            </contact>
            <bounce/>
            <friction>
              <torsional>
                <ode/>
              </torsional>
              <ode/>
            </friction>
          </surface>
        </collision>
        <collision name='front_left_wheel_collision'>
          <pose frame=''>0.31103 -0.32115 0.1358 1.5707 0 1.5707</pose>
          <geometry>
            <cylinder>
              <radius>0.1358</radius>
              <length>0.1641</length>
            </cylinder>
          </geometry>
          <max_contacts>10</max_contacts>
          <surface>
            <contact>
              <ode/>
            </contact>
            <bounce/>
            <friction>
              <torsional>
                <ode/>
              </torsional>
              <ode/>
            </friction>
          </surface>
        </collision>
        <collision name='front_right_wheel_collision'>
          <pose frame=''>-0.31103 -0.32115 0.1358 1.5707 0 1.5707</pose>
          <geometry>
            <cylinder>
              <radius>0.1358</radius>
              <length>0.1641</length>
            </cylinder>
          </geometry>
          <max_contacts>10</max_contacts>
          <surface>
            <contact>
              <ode/>
            </contact>
            <bounce/>
            <friction>
              <torsional>
                <ode/>
              </torsional>
              <ode/>
            </friction>
          </surface>
        </collision>
        <collision name='rear_left_wheel_collision'>
          <pose frame=''>0.31103 0.28049 0.1358 1.5707 0 1.5707</pose>
          <geometry>
            <cylinder>
              <radius>0.1358</radius>
              <length>0.1641</length>
            </cylinder>
          </geometry>
          <max_contacts>10</max_contacts>
          <surface>
            <contact>
              <ode/>
            </contact>
            <bounce/>
            <friction>
              <torsional>
                <ode/>
              </torsional>
              <ode/>
            </friction>
          </surface>
        </collision>
        <collision name='rear_right_wheel_collision'>
          <pose frame=''>-0.31103 0.28049 0.1358 1.5707 0 1.5707</pose>
          <geometry>
            <cylinder>
              <radius>0.1358</radius>
              <length>0.1641</length>
            </cylinder>
          </geometry>
          <max_contacts>10</max_contacts>
          <surface>
            <contact>
              <ode/>
            </contact>
            <bounce/>
            <friction>
              <torsional>
                <ode/>
              </torsional>
              <ode/>
            </friction>
          </surface>
        </collision>
        <visual name='visual'>
          <geometry>
            <mesh>
              <uri>model://mars_rover/meshes/rover.dae</uri>
            </mesh>
          </geometry>
        </visual>
        <self_collide>0</self_collide>
        <enable_wind>0</enable_wind>
        <kinematic>0</kinematic>
      </link>
      <pose frame=''>-0.820999 -0.667492 0 0 -0 0</pose>
    </model>
    <model name='iss'>
      <static>1</static>
      <pose frame=''>-0.34103 2.10464 4.6 3.14 -0 3.14</pose>
      <link name='body'>
        <inertial>
          <mass>0.1</mass>
          <inertia>
            <ixx>1</ixx>
            <ixy>0</ixy>
            <ixz>0</ixz>
            <iyy>1</iyy>
            <iyz>0</iyz>
            <izz>1</izz>
          </inertia>
        </inertial>
        <collision name='ISS_Surface'>
          <geometry>
            <mesh>
              <uri>model://iss/meshes/US_Lab_ISS4.dae</uri>
            </mesh>
          </geometry>
          <max_contacts>10</max_contacts>
          <surface>
            <contact>
              <ode/>
            </contact>
            <bounce/>
            <friction>
              <torsional>
                <ode/>
              </torsional>
              <ode/>
            </friction>
          </surface>
        </collision>
        <visual name='ISS_Visual'>
          <geometry>
            <mesh>
              <uri>model://iss/meshes//US_Lab_ISS4.dae</uri>
            </mesh>
          </geometry>
        </visual>
        <self_collide>0</self_collide>
        <enable_wind>0</enable_wind>
        <kinematic>0</kinematic>
      </link>
    </model>
    <model name='unit_box_clone_0_clone'>
      <pose frame=''>5.31123 -8.78935 0.499974 -3e-06 -4e-06 1.09907</pose>
      <link name='link'>
        <inertial>
          <mass>1</mass>
          <inertia>
            <ixx>0.166667</ixx>
            <ixy>0</ixy>
            <ixz>0</ixz>
            <iyy>0.166667</iyy>
            <iyz>0</iyz>
            <izz>0.166667</izz>
          </inertia>
          <pose frame=''>0 0 0 0 -0 0</pose>
        </inertial>
        <collision name='collision'>
          <geometry>
            <box>
              <size>12.0836 0.030585 1</size>
            </box>
          </geometry>
          <max_contacts>10</max_contacts>
          <surface>
            <contact>
              <ode/>
            </contact>
            <bounce/>
            <friction>
              <torsional>
                <ode/>
              </torsional>
              <ode/>
            </friction>
          </surface>
        </collision>
        <visual name='visual'>
          <geometry>
            <box>
              <size>12.0836 0.030585 1</size>
            </box>
          </geometry>
          <material>
            <script>
              <name>Gazebo/Grey</name>
              <uri>file://media/materials/scripts/gazebo.material</uri>
            </script>
          </material>
        </visual>
        <self_collide>0</self_collide>
        <enable_wind>0</enable_wind>
        <kinematic>0</kinematic>
      </link>
    </model>
    <model name='unit_box_clone_0_clone_0'>
      <pose frame=''>-4.27304 -12.8123 0.499974 -3e-06 -4e-06 1.09907</pose>
      <link name='link'>
        <inertial>
          <mass>1</mass>
          <inertia>
            <ixx>0.166667</ixx>
            <ixy>0</ixy>
            <ixz>0</ixz>
            <iyy>0.166667</iyy>
            <iyz>0</iyz>
            <izz>0.166667</izz>
          </inertia>
          <pose frame=''>0 0 0 0 -0 0</pose>
        </inertial>
        <collision name='collision'>
          <geometry>
            <box>
              <size>12.0836 0.030585 1</size>
            </box>
          </geometry>
          <max_contacts>10</max_contacts>
          <surface>
            <contact>
              <ode/>
            </contact>
            <bounce/>
            <friction>
              <torsional>
                <ode/>
              </torsional>
              <ode/>
            </friction>
          </surface>
        </collision>
        <visual name='visual'>
          <geometry>
            <box>
              <size>12.0836 0.030585 1</size>
            </box>
          </geometry>
          <material>
            <script>
              <name>Gazebo/Grey</name>
              <uri>file://media/materials/scripts/gazebo.material</uri>
            </script>
          </material>
        </visual>
        <self_collide>0</self_collide>
        <enable_wind>0</enable_wind>
        <kinematic>0</kinematic>
      </link>
    </model>
    <model name='unit_box_clone_0_clone_1'>
      <pose frame=''>-18.3345 -7.8891 0.499974 -3e-06 -4e-06 1.09907</pose>
      <link name='link'>
        <inertial>
          <mass>1</mass>
          <inertia>
            <ixx>0.166667</ixx>
            <ixy>0</ixy>
            <ixz>0</ixz>
            <iyy>0.166667</iyy>
            <iyz>0</iyz>
            <izz>0.166667</izz>
          </inertia>
          <pose frame=''>0 0 0 0 -0 0</pose>
        </inertial>
        <collision name='collision'>
          <geometry>
            <box>
              <size>12.0836 0.030585 1</size>
            </box>
          </geometry>
          <max_contacts>10</max_contacts>
          <surface>
            <contact>
              <ode/>
            </contact>
            <bounce/>
            <friction>
              <torsional>
                <ode/>
              </torsional>
              <ode/>
            </friction>
          </surface>
        </collision>
        <visual name='visual'>
          <geometry>
            <box>
              <size>12.0836 0.030585 1</size>
            </box>
          </geometry>
          <material>
            <script>
              <name>Gazebo/Grey</name>
              <uri>file://media/materials/scripts/gazebo.material</uri>
            </script>
          </material>
        </visual>
        <self_collide>0</self_collide>
        <enable_wind>0</enable_wind>
        <kinematic>0</kinematic>
      </link>
    </model>
    <model name='unit_box_clone_0_clone_2'>
      <pose frame=''>-12.9168 2.92338 0.499974 -3e-06 -4e-06 1.09907</pose>
      <link name='link'>
        <inertial>
          <mass>1</mass>
          <inertia>
            <ixx>0.166667</ixx>
            <ixy>0</ixy>
            <ixz>0</ixz>
            <iyy>0.166667</iyy>
            <iyz>0</iyz>
            <izz>0.166667</izz>
          </inertia>
          <pose frame=''>0 0 0 0 -0 0</pose>
        </inertial>
        <collision name='collision'>
          <geometry>
            <box>
              <size>12.0836 0.030585 1</size>
            </box>
          </geometry>
          <max_contacts>10</max_contacts>
          <surface>
            <contact>
              <ode/>
            </contact>
            <bounce/>
            <friction>
              <torsional>
                <ode/>
              </torsional>
              <ode/>
            </friction>
          </surface>
        </collision>
        <visual name='visual'>
          <geometry>
            <box>
              <size>12.0836 0.030585 1</size>
            </box>
          </geometry>
          <material>
            <script>
              <name>Gazebo/Grey</name>
              <uri>file://media/materials/scripts/gazebo.material</uri>
            </script>
          </material>
        </visual>
        <self_collide>0</self_collide>
        <enable_wind>0</enable_wind>
        <kinematic>0</kinematic>
      </link>
    </model>
    <model name='unit_box_clone_0_clone_3'>
      <pose frame=''>-7.49296 13.5602 0.499974 -3e-06 -4e-06 1.09907</pose>
      <link name='link'>
        <inertial>
          <mass>1</mass>
          <inertia>
            <ixx>0.166667</ixx>
            <ixy>0</ixy>
            <ixz>0</ixz>
            <iyy>0.166667</iyy>
            <iyz>0</iyz>
            <izz>0.166667</izz>
          </inertia>
          <pose frame=''>0 0 0 0 -0 0</pose>
        </inertial>
        <collision name='collision'>
          <geometry>
            <box>
              <size>12.0836 0.030585 1</size>
            </box>
          </geometry>
          <max_contacts>10</max_contacts>
          <surface>
            <contact>
              <ode/>
            </contact>
            <bounce/>
            <friction>
              <torsional>
                <ode/>
              </torsional>
              <ode/>
            </friction>
          </surface>
        </collision>
        <visual name='visual'>
          <geometry>
            <box>
              <size>12.0836 0.030585 1</size>
            </box>
          </geometry>
          <material>
            <script>
              <name>Gazebo/Grey</name>
              <uri>file://media/materials/scripts/gazebo.material</uri>
            </script>
          </material>
        </visual>
        <self_collide>0</self_collide>
        <enable_wind>0</enable_wind>
        <kinematic>0</kinematic>
      </link>
    </model>
    <model name='unit_box_clone_0_clone_4'>
      <pose frame=''>14.6615 10.1905 0.499974 -3e-06 -4e-06 1.09907</pose>
      <link name='link'>
        <inertial>
          <mass>1</mass>
          <inertia>
            <ixx>0.166667</ixx>
            <ixy>0</ixy>
            <ixz>0</ixz>
            <iyy>0.166667</iyy>
            <iyz>0</iyz>
            <izz>0.166667</izz>
          </inertia>
          <pose frame=''>0 0 0 0 -0 0</pose>
        </inertial>
        <collision name='collision'>
          <geometry>
            <box>
              <size>12.0836 0.030585 1</size>
            </box>
          </geometry>
          <max_contacts>10</max_contacts>
          <surface>
            <contact>
              <ode/>
            </contact>
            <bounce/>
            <friction>
              <torsional>
                <ode/>
              </torsional>
              <ode/>
            </friction>
          </surface>
        </collision>
        <visual name='visual'>
          <geometry>
            <box>
              <size>12.0836 0.030585 1</size>
            </box>
          </geometry>
          <material>
            <script>
              <name>Gazebo/Grey</name>
              <uri>file://media/materials/scripts/gazebo.material</uri>
            </script>
          </material>
        </visual>
        <self_collide>0</self_collide>
        <enable_wind>0</enable_wind>
        <kinematic>0</kinematic>
      </link>
    </model>
    <model name='unit_box_clone_0_clone_0_clone'>
      <pose frame=''>-11.4539 -14.1011 0.499834 1.8e-05 2.8e-05 -0.357844</pose>
      <link name='link'>
        <inertial>
          <mass>1</mass>
          <inertia>
            <ixx>0.166667</ixx>
            <ixy>0</ixy>
            <ixz>0</ixz>
            <iyy>0.166667</iyy>
            <iyz>0</iyz>
            <izz>0.166667</izz>
          </inertia>
          <pose frame=''>0 0 0 0 -0 0</pose>
        </inertial>
        <collision name='collision'>
          <geometry>
            <box>
              <size>12.0836 0.030585 1</size>
            </box>
          </geometry>
          <max_contacts>10</max_contacts>
          <surface>
            <contact>
              <ode/>
            </contact>
            <bounce/>
            <friction>
              <torsional>
                <ode/>
              </torsional>
              <ode/>
            </friction>
          </surface>
        </collision>
        <visual name='visual'>
          <geometry>
            <box>
              <size>12.0836 0.030585 1</size>
            </box>
          </geometry>
          <material>
            <script>
              <name>Gazebo/Grey</name>
              <uri>file://media/materials/scripts/gazebo.material</uri>
            </script>
          </material>
        </visual>
        <self_collide>0</self_collide>
        <enable_wind>0</enable_wind>
        <kinematic>0</kinematic>
      </link>
    </model>
    <model name='unit_box'>
      <pose frame=''>-8.86356 -8.91096 0.5 0 -0 0</pose>
      <link name='link'>
        <inertial>
          <mass>1</mass>
          <inertia>
            <ixx>0.166667</ixx>
            <ixy>0</ixy>
            <ixz>0</ixz>
            <iyy>0.166667</iyy>
            <iyz>0</iyz>
            <izz>0.166667</izz>
          </inertia>
          <pose frame=''>0 0 0 0 -0 0</pose>
        </inertial>
        <collision name='collision'>
          <geometry>
            <box>
              <size>1 1 1</size>
            </box>
          </geometry>
          <max_contacts>10</max_contacts>
          <surface>
            <contact>
              <ode/>
            </contact>
            <bounce/>
            <friction>
              <torsional>
                <ode/>
              </torsional>
              <ode/>
            </friction>
          </surface>
        </collision>
        <visual name='visual'>
          <geometry>
            <box>
              <size>1 1 1</size>
            </box>
          </geometry>
          <material>
            <script>
              <name>Gazebo/Grey</name>
              <uri>file://media/materials/scripts/gazebo.material</uri>
            </script>
          </material>
        </visual>
        <self_collide>0</self_collide>
        <enable_wind>0</enable_wind>
        <kinematic>0</kinematic>
      </link>
    </model>
    <model name='unit_box_0'>
      <pose frame=''>-8.76534 -7.41361 0.5 0 -0 0</pose>
      <link name='link'>
        <inertial>
          <mass>1</mass>
          <inertia>
            <ixx>0.166667</ixx>
            <ixy>0</ixy>
            <ixz>0</ixz>
            <iyy>0.166667</iyy>
            <iyz>0</iyz>
            <izz>0.166667</izz>
          </inertia>
          <pose frame=''>0 0 0 0 -0 0</pose>
        </inertial>
        <collision name='collision'>
          <geometry>
            <box>
              <size>1 1 1</size>
            </box>
          </geometry>
          <max_contacts>10</max_contacts>
          <surface>
            <contact>
              <ode/>
            </contact>
            <bounce/>
            <friction>
              <torsional>
                <ode/>
              </torsional>
              <ode/>
            </friction>
          </surface>
        </collision>
        <visual name='visual'>
          <geometry>
            <box>
              <size>1 1 1</size>
            </box>
          </geometry>
          <material>
            <script>
              <name>Gazebo/Grey</name>
              <uri>file://media/materials/scripts/gazebo.material</uri>
            </script>
          </material>
        </visual>
        <self_collide>0</self_collide>
        <enable_wind>0</enable_wind>
        <kinematic>0</kinematic>
      </link>
    </model>
    <model name='unit_cylinder'>
      <pose frame=''>-3.59772 -15.5649 0.5 0 -0 0</pose>
      <link name='link'>
        <inertial>
          <mass>1</mass>
          <inertia>
            <ixx>0.145833</ixx>
            <ixy>0</ixy>
            <ixz>0</ixz>
            <iyy>0.145833</iyy>
            <iyz>0</iyz>
            <izz>0.125</izz>
          </inertia>
          <pose frame=''>0 0 0 0 -0 0</pose>
        </inertial>
        <collision name='collision'>
          <geometry>
            <cylinder>
              <radius>0.5</radius>
              <length>1</length>
            </cylinder>
          </geometry>
          <max_contacts>10</max_contacts>
          <surface>
            <contact>
              <ode/>
            </contact>
            <bounce/>
            <friction>
              <torsional>
                <ode/>
              </torsional>
              <ode/>
            </friction>
          </surface>
        </collision>
        <visual name='visual'>
          <geometry>
            <cylinder>
              <radius>0.5</radius>
              <length>1</length>
            </cylinder>
          </geometry>
          <material>
            <script>
              <name>Gazebo/Grey</name>
              <uri>file://media/materials/scripts/gazebo.material</uri>
            </script>
          </material>
        </visual>
        <self_collide>0</self_collide>
        <enable_wind>0</enable_wind>
        <kinematic>0</kinematic>
      </link>
    </model>
    <model name='unit_box_clone_0_clone_0_clone_0'>
      <pose frame=''>-3.67902 -3.72552 0.499902 -8e-06 -1.6e-05 -0.355285</pose>
      <link name='link'>
        <inertial>
          <mass>1</mass>
          <inertia>
            <ixx>0.166667</ixx>
            <ixy>0</ixy>
            <ixz>0</ixz>
            <iyy>0.166667</iyy>
            <iyz>0</iyz>
            <izz>0.166667</izz>
          </inertia>
          <pose frame=''>0 0 0 0 -0 0</pose>
        </inertial>
        <collision name='collision'>
          <geometry>
            <box>
              <size>12.0836 0.030585 1</size>
            </box>
          </geometry>
          <max_contacts>10</max_contacts>
          <surface>
            <contact>
              <ode/>
            </contact>
            <bounce/>
            <friction>
              <torsional>
                <ode/>
              </torsional>
              <ode/>
            </friction>
          </surface>
        </collision>
        <visual name='visual'>
          <geometry>
            <box>
              <size>12.0836 0.030585 1</size>
            </box>
          </geometry>
          <material>
            <script>
              <name>Gazebo/Grey</name>
              <uri>file://media/materials/scripts/gazebo.material</uri>
            </script>
          </material>
        </visual>
        <self_collide>0</self_collide>
        <enable_wind>0</enable_wind>
        <kinematic>0</kinematic>
      </link>
    </model>
    <model name='hsrb'>
      <link name='base_footprint'>
        <pose frame=''>0 0 0 0 -0 0</pose>
        <inertial>
          <pose frame=''>-0.025934 -0.00547 0.176333 0 -0 0</pose>
          <mass>50.02</mass>
          <inertia>
            <ixx>0.376384</ixx>
            <ixy>0.000387825</ixy>
            <ixz>0.0308632</ixz>
            <iyy>0.345982</iyy>
            <iyz>0.0177433</iyz>
            <izz>0.153464</izz>
          </inertia>
        </inertial>
        <collision name='base_footprint_fixed_joint_lump__base_link_collision'>
          <pose frame=''>0 0 0 0 -0 0</pose>
          <geometry>
            <mesh>
              <scale>1 1 1</scale>
              <uri>/opt/ros/melodic/share/hsrb_description/meshes/base_v2/base.stl</uri>
            </mesh>
          </geometry>
          <surface>
            <contact>
              <ode/>
            </contact>
            <friction>
              <ode>
                <mu>0.9</mu>
                <mu2>0.9</mu2>
              </ode>
              <torsional>
                <ode/>
              </torsional>
            </friction>
            <bounce/>
          </surface>
          <max_contacts>10</max_contacts>
        </collision>
        <collision name='base_footprint_fixed_joint_lump__base_range_sensor_link_collision_1'>
          <pose frame=''>0.1675 0 0.1844 0 -0 0</pose>
          <geometry>
            <mesh>
              <scale>1 1 1</scale>
              <uri>/opt/ros/melodic/share/hsrb_parts_description/meshes/sensors/laser.stl</uri>
            </mesh>
          </geometry>
          <surface>
            <contact>
              <ode/>
            </contact>
            <friction>
              <ode>
                <mu>0.9</mu>
                <mu2>0.9</mu2>
              </ode>
              <torsional>
                <ode/>
              </torsional>
            </friction>
            <bounce/>
          </surface>
          <max_contacts>10</max_contacts>
        </collision>
        <visual name='base_footprint_fixed_joint_lump__base_link_visual'>
          <pose frame=''>0 0 0 0 -0 0</pose>
          <geometry>
            <mesh>
              <scale>1 1 1</scale>
              <uri>/opt/ros/melodic/share/hsrb_description/meshes/base_v2/base_light.dae</uri>
            </mesh>
          </geometry>
          <material>
            <script>
              <uri>__default__</uri>
              <name>__default__</name>
            </script>
          </material>
        </visual>
        <visual name='base_footprint_fixed_joint_lump__base_link_visual_1'>
          <pose frame=''>0 0 0 0 -0 0</pose>
          <geometry>
            <mesh>
              <scale>1 1 1</scale>
              <uri>/opt/ros/melodic/share/hsrb_description/meshes/base_v2/body_light.dae</uri>
            </mesh>
          </geometry>
          <material>
            <script>
              <uri>__default__</uri>
              <name>__default__</name>
            </script>
          </material>
        </visual>
        <visual name='base_footprint_fixed_joint_lump__base_link_visual_2'>
          <pose frame=''>0 0 0 0 -0 0</pose>
          <geometry>
            <mesh>
              <scale>1 1 1</scale>
              <uri>/opt/ros/melodic/share/hsrb_description/meshes/base_v2/torso_base.dae</uri>
            </mesh>
          </geometry>
          <material>
            <script>
              <uri>__default__</uri>
              <name>__default__</name>
            </script>
          </material>
        </visual>
        <visual name='base_footprint_fixed_joint_lump__base_range_sensor_link_visual_3'>
          <pose frame=''>0.1675 0 0.1844 0 -0 0</pose>
          <geometry>
            <mesh>
              <scale>1 1 1</scale>
              <uri>/opt/ros/melodic/share/hsrb_parts_description/meshes/sensors/laser.dae</uri>
            </mesh>
          </geometry>
          <material>
            <script>
              <uri>__default__</uri>
              <name>__default__</name>
            </script>
          </material>
        </visual>
        <velocity_decay/>
        <velocity_decay/>
        <sensor name='base_imu' type='imu'>
          <update_rate>100</update_rate>
          <plugin name='base_imu_plugin' filename='libgazebo_ros_imu_sensor.so'>
            <updateRateHZ>100.0</updateRateHZ>
            <bodyName>base_link</bodyName>
            <topicName>hsrb/base_imu/data</topicName>
            <frameName>/base_imu_frame</frameName>
            <gaussianNoise>0.0</gaussianNoise>
            <xyzOffset>0.0 0.0 0.0</xyzOffset>
            <rpyOffset>0.0 -0.0 0.0</rpyOffset>
            <robotNamespace>/</robotNamespace>
          </plugin>
          <imu>
            <angular_velocity>
              <x>
                <noise type='gaussian'>
                  <mean>0</mean>
                  <stddev>0.0002</stddev>
                  <bias_mean>7.5e-06</bias_mean>
                  <bias_stddev>8e-07</bias_stddev>
                </noise>
              </x>
              <y>
                <noise type='gaussian'>
                  <mean>0</mean>
                  <stddev>0.0002</stddev>
                  <bias_mean>7.5e-06</bias_mean>
                  <bias_stddev>8e-07</bias_stddev>
                </noise>
              </y>
              <z>
                <noise type='gaussian'>
                  <mean>0</mean>
                  <stddev>0.0002</stddev>
                  <bias_mean>7.5e-06</bias_mean>
                  <bias_stddev>8e-07</bias_stddev>
                </noise>
              </z>
            </angular_velocity>
            <linear_acceleration>
              <x>
                <noise type='gaussian'>
                  <mean>0</mean>
                  <stddev>0.017</stddev>
                  <bias_mean>0.1</bias_mean>
                  <bias_stddev>0.001</bias_stddev>
                </noise>
              </x>
              <y>
                <noise type='gaussian'>
                  <mean>0</mean>
                  <stddev>0.017</stddev>
                  <bias_mean>0.1</bias_mean>
                  <bias_stddev>0.001</bias_stddev>
                </noise>
              </y>
              <z>
                <noise type='gaussian'>
                  <mean>0</mean>
                  <stddev>0.017</stddev>
                  <bias_mean>0.1</bias_mean>
                  <bias_stddev>0.001</bias_stddev>
                </noise>
              </z>
            </linear_acceleration>
          </imu>
          <pose frame=''>0.0005 0.1296 0.181 0 -0 0</pose>
        </sensor>
        <velocity_decay/>
        <gravity>1</gravity>
        <gravity>1</gravity>
        <velocity_decay/>
        <sensor name='base_range_sensor' type='ray'>
          <update_rate>30</update_rate>
          <visualize>0</visualize>
          <ray>
            <scan>
              <horizontal>
                <samples>721</samples>
                <resolution>1</resolution>
                <min_angle>-2.1</min_angle>
                <max_angle>2.1</max_angle>
              </horizontal>
              <vertical>
                <samples>1</samples>
                <min_angle>0</min_angle>
                <max_angle>0</max_angle>
              </vertical>
            </scan>
            <range>
              <min>0.05</min>
              <max>60</max>
              <resolution>0.001</resolution>
            </range>
          </ray>
          <plugin name='hokuyo_laser' filename='libgazebo_ros_laser.so'>
            <topicName>hsrb/base_scan</topicName>
            <frameName>base_range_sensor_link</frameName>
            <robotNamespace>/</robotNamespace>
          </plugin>
          <pose frame=''>0.1675 0 0.1844 0 -0 0</pose>
        </sensor>
        <gravity>1</gravity>
        <velocity_decay/>
        <self_collide>0</self_collide>
        <gravity>1</gravity>
        <enable_wind>0</enable_wind>
        <kinematic>0</kinematic>
      </link>
      <link name='arm_lift_link'>
        <pose frame=''>0 0 0.34 0 -0 0</pose>
        <inertial>
          <pose frame=''>0.051549 0.042438 -0.064145 0 -0 0</pose>
          <mass>1.27582</mass>
          <inertia>
            <ixx>0.004633</ixx>
            <ixy>0.000475273</ixy>
            <ixz>-0.002403</ixz>
            <iyy>0.008065</iyy>
            <iyz>-0.000100269</iyz>
            <izz>0.007672</izz>
          </inertia>
        </inertial>
        <collision name='arm_lift_link_collision'>
          <pose frame=''>0 0 0 0 -0 0</pose>
          <geometry>
            <mesh>
              <scale>1 1 1</scale>
              <uri>/opt/ros/melodic/share/hsrb_description/meshes/arm_v0/shoulder.stl</uri>
            </mesh>
          </geometry>
          <surface>
            <contact>
              <ode/>
            </contact>
            <friction>
              <ode>
                <mu>0.9</mu>
                <mu2>0.9</mu2>
              </ode>
              <torsional>
                <ode/>
              </torsional>
            </friction>
            <bounce/>
          </surface>
          <max_contacts>10</max_contacts>
        </collision>
        <visual name='arm_lift_link_visual'>
          <pose frame=''>0 0 0 0 -0 0</pose>
          <geometry>
            <mesh>
              <scale>1 1 1</scale>
              <uri>/opt/ros/melodic/share/hsrb_description/meshes/arm_v0/shoulder.dae</uri>
            </mesh>
          </geometry>
          <material>
            <script>
              <uri>__default__</uri>
              <name>__default__</name>
            </script>
          </material>
        </visual>
        <gravity>1</gravity>
        <velocity_decay/>
        <self_collide>0</self_collide>
        <gravity>1</gravity>
        <enable_wind>0</enable_wind>
        <kinematic>0</kinematic>
      </link>
      <joint name='arm_lift_joint' type='prismatic'>
        <child>arm_lift_link</child>
        <parent>base_footprint</parent>
        <axis>
          <xyz>0 0 1</xyz>
          <limit>
            <lower>0</lower>
            <upper>0.69</upper>
            <effort>300</effort>
            <velocity>0.2</velocity>
          </limit>
          <dynamics>
            <damping>1</damping>
            <friction>0</friction>
            <spring_reference>0</spring_reference>
            <spring_stiffness>0</spring_stiffness>
          </dynamics>
          <use_parent_model_frame>1</use_parent_model_frame>
        </axis>
        <physics>
          <ode>
            <limit>
              <cfm>0</cfm>
              <erp>0.2</erp>
            </limit>
          </ode>
        </physics>
      </joint>
      <link name='arm_flex_link'>
        <pose frame=''>0.141 0.078 0.34 0 -0 0</pose>
        <inertial>
          <pose frame=''>0.000632 0.006404 0.118529 0 -0 0</pose>
          <mass>1.33929</mass>
          <inertia>
            <ixx>7.528</ixx>
            <ixy>-2.02842e-05</ixy>
            <ixz>-2.29472e-05</ixz>
            <iyy>0.007102</iyy>
            <iyz>-9.17961e-05</iyz>
            <izz>0.001552</izz>
          </inertia>
        </inertial>
        <collision name='arm_flex_link_collision'>
          <pose frame=''>0 0 0 0 -0 0</pose>
          <geometry>
            <mesh>
              <scale>1 1 1</scale>
              <uri>/opt/ros/melodic/share/hsrb_description/meshes/arm_v0/arm_flex.stl</uri>
            </mesh>
          </geometry>
          <surface>
            <contact>
              <ode/>
            </contact>
            <friction>
              <ode>
                <mu>0.9</mu>
                <mu2>0.9</mu2>
              </ode>
              <torsional>
                <ode/>
              </torsional>
            </friction>
            <bounce/>
          </surface>
          <max_contacts>10</max_contacts>
        </collision>
        <visual name='arm_flex_link_visual'>
          <pose frame=''>0 0 0 0 -0 0</pose>
          <geometry>
            <mesh>
              <scale>1 1 1</scale>
              <uri>/opt/ros/melodic/share/hsrb_description/meshes/arm_v0/arm_flex_light.dae</uri>
            </mesh>
          </geometry>
          <material>
            <script>
              <uri>__default__</uri>
              <name>__default__</name>
            </script>
          </material>
        </visual>
        <gravity>1</gravity>
        <velocity_decay/>
        <self_collide>0</self_collide>
        <gravity>1</gravity>
        <enable_wind>0</enable_wind>
        <kinematic>0</kinematic>
      </link>
      <joint name='arm_flex_joint' type='revolute'>
        <child>arm_flex_link</child>
        <parent>arm_lift_link</parent>
        <axis>
          <xyz>0 -1 0</xyz>
          <limit>
            <lower>-2.62</lower>
            <upper>0</upper>
            <effort>100</effort>
            <velocity>1.2</velocity>
          </limit>
          <dynamics>
            <damping>1</damping>
            <friction>0</friction>
            <spring_reference>0</spring_reference>
            <spring_stiffness>0</spring_stiffness>
          </dynamics>
          <use_parent_model_frame>1</use_parent_model_frame>
        </axis>
        <physics>
          <ode>
            <limit>
              <cfm>0</cfm>
              <erp>0.2</erp>
            </limit>
          </ode>
        </physics>
      </joint>
      <link name='arm_roll_link'>
        <pose frame=''>0.146 0.078 0.685 0 -0 0</pose>
        <inertial>
          <pose frame=''>-0.006927 0.002039 -0.064837 0 -0 0</pose>
          <mass>0.247936</mass>
          <inertia>
            <ixx>0.004267</ixx>
            <ixy>-1.83222e-05</ixy>
            <ixz>1.79845e-05</ixz>
            <iyy>0.000780924</iyy>
            <iyz>-1.39233e-05</iyz>
            <izz>0.00412</izz>
          </inertia>
        </inertial>
        <collision name='arm_roll_link_collision'>
          <pose frame=''>0 0 0 0 -0 0</pose>
          <geometry>
            <mesh>
              <scale>1 1 1</scale>
              <uri>/opt/ros/melodic/share/hsrb_description/meshes/arm_v0/arm_roll.stl</uri>
            </mesh>
          </geometry>
          <surface>
            <contact>
              <ode/>
            </contact>
            <friction>
              <ode>
                <mu>0.9</mu>
                <mu2>0.9</mu2>
              </ode>
              <torsional>
                <ode/>
              </torsional>
            </friction>
            <bounce/>
          </surface>
          <max_contacts>10</max_contacts>
        </collision>
        <visual name='arm_roll_link_visual'>
          <pose frame=''>0 0 0 0 -0 0</pose>
          <geometry>
            <mesh>
              <scale>1 1 1</scale>
              <uri>/opt/ros/melodic/share/hsrb_description/meshes/arm_v0/arm_roll_light.dae</uri>
            </mesh>
          </geometry>
          <material>
            <script>
              <uri>__default__</uri>
              <name>__default__</name>
            </script>
          </material>
        </visual>
        <gravity>1</gravity>
        <velocity_decay/>
        <self_collide>0</self_collide>
        <gravity>1</gravity>
        <enable_wind>0</enable_wind>
        <kinematic>0</kinematic>
      </link>
      <joint name='arm_roll_joint' type='revolute'>
        <child>arm_roll_link</child>
        <parent>arm_flex_link</parent>
        <axis>
          <xyz>0 0 1</xyz>
          <limit>
            <lower>-2.09</lower>
            <upper>3.84</upper>
            <effort>100</effort>
            <velocity>2</velocity>
          </limit>
          <dynamics>
            <damping>0.1</damping>
            <friction>0</friction>
            <spring_reference>0</spring_reference>
            <spring_stiffness>0</spring_stiffness>
          </dynamics>
          <use_parent_model_frame>1</use_parent_model_frame>
        </axis>
        <physics>
          <ode>
            <limit>
              <cfm>0</cfm>
              <erp>0.2</erp>
            </limit>
          </ode>
        </physics>
      </joint>
      <link name='wrist_flex_link'>
        <pose frame=''>0.146 0.078 0.685 0 -0 0</pose>
        <inertial>
          <pose frame=''>0.000131 -0.003929 0.00217 0 -0 0</pose>
          <mass>0.681225</mass>
          <inertia>
            <ixx>7.43536e-05</ixx>
            <ixy>4.94515e-07</ixy>
            <ixz>2.2937e-08</ixz>
            <iyy>3.84329e-05</iyy>
            <iyz>-2.55576e-06</iyz>
            <izz>6.46809e-05</izz>
          </inertia>
        </inertial>
        <collision name='wrist_flex_link_collision'>
          <pose frame=''>0 0 0.03 0 -0 0</pose>
          <geometry>
            <cylinder>
              <length>0.04</length>
              <radius>0.017</radius>
            </cylinder>
          </geometry>
          <surface>
            <contact>
              <ode/>
            </contact>
            <friction>
              <ode>
                <mu>0.9</mu>
                <mu2>0.9</mu2>
              </ode>
              <torsional>
                <ode/>
              </torsional>
            </friction>
            <bounce/>
          </surface>
          <max_contacts>10</max_contacts>
        </collision>
        <visual name='wrist_flex_link_visual'>
          <pose frame=''>0 0 0 0 -0 0</pose>
          <geometry>
            <mesh>
              <scale>1 1 1</scale>
              <uri>/opt/ros/melodic/share/hsrb_description/meshes/wrist_v0/wrist_flex.dae</uri>
            </mesh>
          </geometry>
          <material>
            <script>
              <uri>__default__</uri>
              <name>__default__</name>
            </script>
          </material>
        </visual>
        <visual name='wrist_flex_link_visual_1'>
          <pose frame=''>0 0 0.04 0 -0 0</pose>
          <geometry>
            <cylinder>
              <length>0.02</length>
              <radius>0.017</radius>
            </cylinder>
          </geometry>
          <material>
            <script>
              <uri>__default__</uri>
              <name>__default__</name>
            </script>
          </material>
        </visual>
        <gravity>1</gravity>
        <velocity_decay/>
        <self_collide>0</self_collide>
        <gravity>1</gravity>
        <enable_wind>0</enable_wind>
        <kinematic>0</kinematic>
      </link>
      <joint name='wrist_flex_joint' type='revolute'>
        <child>wrist_flex_link</child>
        <parent>arm_roll_link</parent>
        <axis>
          <xyz>0 -1 0</xyz>
          <limit>
            <lower>-1.92</lower>
            <upper>1.22</upper>
            <effort>100</effort>
            <velocity>1.5</velocity>
          </limit>
          <dynamics>
            <damping>1</damping>
            <friction>0</friction>
            <spring_reference>0</spring_reference>
            <spring_stiffness>0</spring_stiffness>
          </dynamics>
          <use_parent_model_frame>1</use_parent_model_frame>
        </axis>
        <physics>
          <ode>
            <limit>
              <cfm>0</cfm>
              <erp>0.2</erp>
            </limit>
          </ode>
        </physics>
      </joint>
      <link name='wrist_ft_sensor_mount_link'>
        <pose frame=''>0.146 0.078 0.685 0 -0 0</pose>
        <inertial>
          <pose frame=''>0 0 0 0 -0 0</pose>
          <mass>0.01</mass>
          <inertia>
            <ixx>0.001</ixx>
            <ixy>0</ixy>
            <ixz>0</ixz>
            <iyy>0.001</iyy>
            <iyz>0</iyz>
            <izz>0.001</izz>
          </inertia>
        </inertial>
        <self_collide>0</self_collide>
        <enable_wind>0</enable_wind>
        <kinematic>0</kinematic>
      </link>
      <joint name='wrist_roll_joint' type='revolute'>
        <child>wrist_ft_sensor_mount_link</child>
        <parent>wrist_flex_link</parent>
        <axis>
          <xyz>0 0 1</xyz>
          <limit>
            <lower>-1.92</lower>
            <upper>3.67</upper>
            <effort>100</effort>
            <velocity>1.5</velocity>
          </limit>
          <dynamics>
            <damping>1</damping>
            <friction>0</friction>
            <spring_reference>0</spring_reference>
            <spring_stiffness>0</spring_stiffness>
          </dynamics>
          <use_parent_model_frame>1</use_parent_model_frame>
        </axis>
        <physics>
          <ode>
            <limit>
              <cfm>0</cfm>
              <erp>0.2</erp>
            </limit>
          </ode>
        </physics>
      </joint>
      <link name='wrist_ft_sensor_frame'>
        <pose frame=''>0.146 0.078 0.7585 -3.14159 -0 0</pose>
        <inertial>
          <pose frame=''>0.000193 0.001251 -0.018623 0 -0 0</pose>
          <mass>0.941692</mass>
          <inertia>
            <ixx>0.0192819</ixx>
            <ixy>1.63273e-05</ixy>
            <ixz>4.64339e-05</ixz>
            <iyy>0.0192817</iyy>
            <iyz>1.0165e-05</iyz>
            <izz>0.0184914</izz>
          </inertia>
        </inertial>
        <collision name='wrist_ft_sensor_frame_fixed_joint_lump__wrist_roll_link_collision'>
          <pose frame=''>0 0 0.0735 3.14159 -0 0</pose>
          <geometry>
            <mesh>
              <scale>1 1 1</scale>
              <uri>/opt/ros/melodic/share/hsrb_description/meshes/wrist_v0/wrist_roll.stl</uri>
            </mesh>
          </geometry>
          <surface>
            <contact>
              <ode/>
            </contact>
            <friction>
              <ode>
                <mu>0.9</mu>
                <mu2>0.9</mu2>
              </ode>
              <torsional>
                <ode/>
              </torsional>
            </friction>
            <bounce/>
          </surface>
          <max_contacts>10</max_contacts>
        </collision>
        <collision name='wrist_ft_sensor_frame_fixed_joint_lump__hand_palm_link_collision_1'>
          <pose frame=''>0.012 -0 -0.067 -3.14159 -0 3.14159</pose>
          <geometry>
            <mesh>
              <scale>1 1 1</scale>
              <uri>/opt/ros/melodic/share/hsrb_description/meshes/hand_v0/palm.stl</uri>
            </mesh>
          </geometry>
          <surface>
            <contact>
              <ode/>
            </contact>
            <friction>
              <ode>
                <mu>0.9</mu>
                <mu2>0.9</mu2>
              </ode>
              <torsional>
                <ode/>
              </torsional>
            </friction>
            <bounce/>
          </surface>
          <max_contacts>10</max_contacts>
        </collision>
        <visual name='wrist_ft_sensor_frame_fixed_joint_lump__wrist_roll_link_visual'>
          <pose frame=''>0 0 0.0735 3.14159 -0 0</pose>
          <geometry>
            <mesh>
              <scale>1 1 1</scale>
              <uri>/opt/ros/melodic/share/hsrb_description/meshes/wrist_v0/wrist_roll.dae</uri>
            </mesh>
          </geometry>
          <material>
            <script>
              <uri>__default__</uri>
              <name>__default__</name>
            </script>
          </material>
        </visual>
        <visual name='wrist_ft_sensor_frame_fixed_joint_lump__hand_palm_link_visual_1'>
          <pose frame=''>0.012 -0 -0.067 -3.14159 -0 3.14159</pose>
          <geometry>
            <mesh>
              <scale>1 1 1</scale>
              <uri>/opt/ros/melodic/share/hsrb_description/meshes/hand_v0/palm_light.dae</uri>
            </mesh>
          </geometry>
          <material>
            <script>
              <uri>__default__</uri>
              <name>__default__</name>
            </script>
          </material>
        </visual>
        <velocity_decay/>
        <velocity_decay/>
        <gravity>1</gravity>
        <velocity_decay/>
        <gravity>1</gravity>
        <gravity>1</gravity>
        <velocity_decay/>
        <self_collide>0</self_collide>
        <gravity>0</gravity>
        <gravity>1</gravity>
        <velocity_decay/>
        <sensor name='hand_camera' type='camera'>
          <update_rate>10</update_rate>
          <camera name='hand_camera'>
            <horizontal_fov>2</horizontal_fov>
            <image>
              <width>640</width>
              <height>480</height>
              <format>R8G8B8</format>
            </image>
            <clip>
              <near>0.01</near>
              <far>100</far>
            </clip>
            <noise>
              <type>gaussian</type>
              <mean>0</mean>
              <stddev>0.007</stddev>
            </noise>
          </camera>
          <plugin name='camera_controller' filename='libhsrb_gazebo_ros_camera.so'>
            <robotNamespace>/hsrb</robotNamespace>
            <alwaysOn>0</alwaysOn>
            <updateRate>0.0</updateRate>
            <cameraName>hand_camera</cameraName>
            <imageTopicName>image_raw</imageTopicName>
            <cameraInfoTopicName>camera_info</cameraInfoTopicName>
            <frameName>hand_camera_frame</frameName>
            <hackBaseline>0.07</hackBaseline>
            <distortionK1>0.0</distortionK1>
            <distortionK2>0.0</distortionK2>
            <distortionK3>0.0</distortionK3>
            <distortionT1>0.0</distortionT1>
            <distortionT2>0.0</distortionT2>
          </plugin>
          <pose frame=''>-0.027 -0 -0.0625 -3.14159 1.57079 1.57079</pose>
        </sensor>
        <enable_wind>0</enable_wind>
        <kinematic>0</kinematic>
      </link>
      <joint name='wrist_ft_sensor_frame_joint' type='revolute'>
        <child>wrist_ft_sensor_frame</child>
        <parent>wrist_ft_sensor_mount_link</parent>
        <axis>
          <xyz>1 0 0</xyz>
          <limit>
            <lower>0</lower>
            <upper>0</upper>
            <effort>100</effort>
            <velocity>1.5</velocity>
          </limit>
          <dynamics>
            <spring_reference>0</spring_reference>
            <spring_stiffness>0</spring_stiffness>
          </dynamics>
          <use_parent_model_frame>1</use_parent_model_frame>
        </axis>
        <physics>
          <provide_feedback>1</provide_feedback>
          <ode>
            <provide_feedback>1</provide_feedback>
            <limit>
              <cfm>0</cfm>
              <erp>0.2</erp>
            </limit>
          </ode>
        </physics>
      </joint>
      <link name='hand_l_proximal_link'>
        <pose frame=''>0.17475 0.1025 0.808 0 -0 -3.14159</pose>
        <inertial>
          <pose frame=''>0 0 0 0 -0 0</pose>
          <mass>0.01</mass>
          <inertia>
            <ixx>0.0015</ixx>
            <ixy>0</ixy>
            <ixz>0</ixz>
            <iyy>0.0015</iyy>
            <iyz>0</iyz>
            <izz>0.0015</izz>
          </inertia>
        </inertial>
        <gravity>1</gravity>
        <velocity_decay/>
        <self_collide>0</self_collide>
        <gravity>1</gravity>
        <enable_wind>0</enable_wind>
        <kinematic>0</kinematic>
      </link>
      <joint name='hand_l_proximal_joint' type='revolute'>
        <child>hand_l_proximal_link</child>
        <parent>wrist_ft_sensor_frame</parent>
        <axis>
          <xyz>-1 -0 0</xyz>
          <limit>
            <lower>-0.798</lower>
            <upper>1.24</upper>
            <effort>100</effort>
            <velocity>1</velocity>
          </limit>
          <dynamics>
            <damping>0.0001</damping>
            <friction>0</friction>
            <spring_reference>0</spring_reference>
            <spring_stiffness>0</spring_stiffness>
          </dynamics>
          <use_parent_model_frame>1</use_parent_model_frame>
        </axis>
        <physics>
          <ode>
            <limit>
              <cfm>0</cfm>
              <erp>0.2</erp>
            </limit>
          </ode>
        </physics>
      </joint>
      <link name='hand_l_spring_proximal_link'>
        <pose frame=''>0.17475 0.1025 0.808 0 -0 -3.14159</pose>
        <inertial>
          <pose frame=''>0.021418 0.00248 0.022688 0 -0 0</pose>
          <mass>0.043589</mass>
          <inertia>
            <ixx>2.60339e-05</ixx>
            <ixy>-1.44078e-07</ixy>
            <ixz>-1.98241e-06</ixz>
            <iyy>2.88248e-05</iyy>
            <iyz>-1.26842e-06</iyz>
            <izz>5.13592e-06</izz>
          </inertia>
        </inertial>
        <collision name='hand_l_spring_proximal_link_collision'>
          <pose frame=''>0 0 0 0 -0 0</pose>
          <geometry>
            <mesh>
              <scale>1 1 1</scale>
              <uri>/opt/ros/melodic/share/hsrb_description/meshes/hand_v0/l_proximal.stl</uri>
            </mesh>
          </geometry>
          <surface>
            <contact>
              <ode/>
            </contact>
            <friction>
              <ode>
                <mu>1</mu>
                <mu2>1</mu2>
              </ode>
              <torsional>
                <ode/>
              </torsional>
            </friction>
            <bounce/>
          </surface>
          <max_contacts>10</max_contacts>
        </collision>
        <visual name='hand_l_spring_proximal_link_visual'>
          <pose frame=''>0 0 0 0 -0 0</pose>
          <geometry>
            <mesh>
              <scale>1 1 1</scale>
              <uri>/opt/ros/melodic/share/hsrb_description/meshes/hand_v0/l_proximal.dae</uri>
            </mesh>
          </geometry>
          <material>
            <script>
              <uri>__default__</uri>
              <name>__default__</name>
            </script>
          </material>
        </visual>
        <gravity>1</gravity>
        <velocity_decay/>
        <self_collide>0</self_collide>
        <gravity>1</gravity>
        <enable_wind>0</enable_wind>
        <kinematic>0</kinematic>
      </link>
      <joint name='hand_l_spring_proximal_joint' type='revolute'>
        <child>hand_l_spring_proximal_link</child>
        <parent>hand_l_proximal_link</parent>
        <axis>
          <xyz>-1 -0 0</xyz>
          <limit>
            <lower>0</lower>
            <upper>0.698</upper>
            <effort>10</effort>
            <velocity>1</velocity>
          </limit>
          <dynamics>
            <damping>0.0001</damping>
            <friction>0</friction>
            <spring_reference>0</spring_reference>
            <spring_stiffness>0</spring_stiffness>
          </dynamics>
          <use_parent_model_frame>1</use_parent_model_frame>
        </axis>
        <physics>
          <ode>
            <limit>
              <cfm>0</cfm>
              <erp>0.2</erp>
            </limit>
          </ode>
        </physics>
      </joint>
      <link name='hand_l_mimic_distal_link'>
        <pose frame=''>0.17475 0.1025 0.878 0 -0 -3.14159</pose>
        <inertial>
          <pose frame=''>0 0 0 0 -0 0</pose>
          <mass>0.01</mass>
          <inertia>
            <ixx>0.0015</ixx>
            <ixy>0</ixy>
            <ixz>0</ixz>
            <iyy>0.0015</iyy>
            <iyz>0</iyz>
            <izz>0.0015</izz>
          </inertia>
        </inertial>
        <gravity>1</gravity>
        <velocity_decay/>
        <self_collide>0</self_collide>
        <gravity>1</gravity>
        <enable_wind>0</enable_wind>
        <kinematic>0</kinematic>
      </link>
      <joint name='hand_l_mimic_distal_joint' type='revolute'>
        <child>hand_l_mimic_distal_link</child>
        <parent>hand_l_spring_proximal_link</parent>
        <axis>
          <xyz>-1 -0 0</xyz>
          <limit>
            <lower>-0.698</lower>
            <upper>-0</upper>
            <effort>100</effort>
            <velocity>1</velocity>
          </limit>
          <dynamics>
            <damping>0.0001</damping>
            <friction>0</friction>
            <spring_reference>0</spring_reference>
            <spring_stiffness>0</spring_stiffness>
          </dynamics>
          <use_parent_model_frame>1</use_parent_model_frame>
        </axis>
        <physics>
          <ode>
            <limit>
              <cfm>0</cfm>
              <erp>0.2</erp>
            </limit>
          </ode>
        </physics>
      </joint>
      <link name='hand_l_distal_link'>
        <pose frame=''>0.17475 0.1025 0.878 0 -0 -3.14159</pose>
        <inertial>
          <pose frame=''>0.010963 0.004789 0.026131 0 -0 0</pose>
          <mass>0.047731</mass>
          <inertia>
            <ixx>0.00301442</ixx>
            <ixy>-2.43794e-06</ixy>
            <ixz>1.08454e-08</ixz>
            <iyy>0.00300659</iyy>
            <iyz>-1.38829e-06</iyz>
            <izz>0.00300979</izz>
          </inertia>
        </inertial>
        <collision name='hand_l_distal_link_collision'>
          <pose frame=''>0 0 0 0 -0 0</pose>
          <geometry>
            <mesh>
              <scale>1 1 1</scale>
              <uri>/opt/ros/melodic/share/hsrb_description/meshes/hand_v0/l_distal.stl</uri>
            </mesh>
          </geometry>
          <surface>
            <contact>
              <ode/>
            </contact>
            <friction>
              <ode>
                <mu>1</mu>
                <mu2>1</mu2>
              </ode>
              <torsional>
                <ode/>
              </torsional>
            </friction>
            <bounce/>
          </surface>
          <max_contacts>10</max_contacts>
        </collision>
        <visual name='hand_l_distal_link_visual'>
          <pose frame=''>0 0 0 0 -0 0</pose>
          <geometry>
            <mesh>
              <scale>1 1 1</scale>
              <uri>/opt/ros/melodic/share/hsrb_description/meshes/hand_v0/l_distal.dae</uri>
            </mesh>
          </geometry>
          <material>
            <script>
              <uri>__default__</uri>
              <name>__default__</name>
            </script>
          </material>
        </visual>
        <visual name='hand_l_distal_link_fixed_joint_lump__hand_l_finger_vacuum_frame_visual_1'>
          <pose frame=''>0.00475 -0.004468 0.026149 0.785398 -0 0</pose>
          <geometry>
            <box>
              <size>0.008 0.008 0.02</size>
            </box>
          </geometry>
          <material>
            <script>
              <uri>__default__</uri>
              <name>__default__</name>
            </script>
          </material>
        </visual>
        <velocity_decay/>
        <gravity>1</gravity>
        <velocity_decay/>
        <gravity>0</gravity>
        <gravity>1</gravity>
        <velocity_decay/>
        <self_collide>0</self_collide>
        <gravity>0</gravity>
        <enable_wind>0</enable_wind>
        <kinematic>0</kinematic>
      </link>
      <joint name='hand_l_distal_joint' type='revolute'>
        <child>hand_l_distal_link</child>
        <parent>hand_l_mimic_distal_link</parent>
        <axis>
          <xyz>-1 -0 0</xyz>
          <limit>
            <lower>-1.24</lower>
            <upper>0.798</upper>
            <effort>100</effort>
            <velocity>1</velocity>
          </limit>
          <dynamics>
            <damping>0.0001</damping>
            <friction>0</friction>
            <spring_reference>0</spring_reference>
            <spring_stiffness>0</spring_stiffness>
          </dynamics>
          <use_parent_model_frame>1</use_parent_model_frame>
        </axis>
        <physics>
          <ode>
            <limit>
              <cfm>0</cfm>
              <erp>0.2</erp>
            </limit>
          </ode>
        </physics>
      </joint>
      <link name='hand_motor_dummy_link'>
        <pose frame=''>0.158 0.078 0.8255 0 -0 -3.14159</pose>
        <inertial>
          <pose frame=''>0 0 0 0 -0 0</pose>
          <mass>0.01</mass>
          <inertia>
            <ixx>0.0015</ixx>
            <ixy>0</ixy>
            <ixz>0</ixz>
            <iyy>0.0015</iyy>
            <iyz>0</iyz>
            <izz>0.0015</izz>
          </inertia>
        </inertial>
        <self_collide>0</self_collide>
        <enable_wind>0</enable_wind>
        <kinematic>0</kinematic>
      </link>
      <joint name='hand_motor_joint' type='revolute'>
        <child>hand_motor_dummy_link</child>
        <parent>wrist_ft_sensor_frame</parent>
        <axis>
          <xyz>-1 -0 0</xyz>
          <limit>
            <lower>-0.798</lower>
            <upper>1.24</upper>
            <effort>100</effort>
            <velocity>1</velocity>
          </limit>
          <dynamics>
            <damping>0.0001</damping>
            <friction>0</friction>
            <spring_reference>0</spring_reference>
            <spring_stiffness>0</spring_stiffness>
          </dynamics>
          <use_parent_model_frame>1</use_parent_model_frame>
        </axis>
        <physics>
          <ode>
            <limit>
              <cfm>0</cfm>
              <erp>0.2</erp>
            </limit>
          </ode>
        </physics>
      </joint>
      <link name='hand_r_proximal_link'>
        <pose frame=''>0.17475 0.0535 0.808 0 -0 -3.14159</pose>
        <inertial>
          <pose frame=''>0 0 0 0 -0 0</pose>
          <mass>0.01</mass>
          <inertia>
            <ixx>0.0015</ixx>
            <ixy>0</ixy>
            <ixz>0</ixz>
            <iyy>0.0015</iyy>
            <iyz>0</iyz>
            <izz>0.0015</izz>
          </inertia>
        </inertial>
        <gravity>1</gravity>
        <velocity_decay/>
        <self_collide>0</self_collide>
        <gravity>1</gravity>
        <enable_wind>0</enable_wind>
        <kinematic>0</kinematic>
      </link>
      <joint name='hand_r_proximal_joint' type='revolute'>
        <child>hand_r_proximal_link</child>
        <parent>wrist_ft_sensor_frame</parent>
        <axis>
          <xyz>1 0 0</xyz>
          <limit>
            <lower>-0.798</lower>
            <upper>1.24</upper>
            <effort>100</effort>
            <velocity>1</velocity>
          </limit>
          <dynamics>
            <damping>0.0001</damping>
            <friction>0</friction>
            <spring_reference>0</spring_reference>
            <spring_stiffness>0</spring_stiffness>
          </dynamics>
          <use_parent_model_frame>1</use_parent_model_frame>
        </axis>
        <physics>
          <ode>
            <limit>
              <cfm>0</cfm>
              <erp>0.2</erp>
            </limit>
          </ode>
        </physics>
      </joint>
      <link name='hand_r_spring_proximal_link'>
        <pose frame=''>0.17475 0.0535 0.808 0 -0 -3.14159</pose>
        <inertial>
          <pose frame=''>0.013203 0.002096 0.023311 0 -0 0</pose>
          <mass>0.043956</mass>
          <inertia>
            <ixx>2.62366e-05</ixx>
            <ixy>1.631e-08</ixy>
            <ixz>1.28184e-06</ixz>
            <iyy>2.88382e-05</iyy>
            <iyz>-1.62171e-06</iyz>
            <izz>4.95715e-06</izz>
          </inertia>
        </inertial>
        <collision name='hand_r_spring_proximal_link_collision'>
          <pose frame=''>0 0 0 0 -0 0</pose>
          <geometry>
            <mesh>
              <scale>1 1 1</scale>
              <uri>/opt/ros/melodic/share/hsrb_description/meshes/hand_v0/r_proximal.stl</uri>
            </mesh>
          </geometry>
          <surface>
            <contact>
              <ode/>
            </contact>
            <friction>
              <ode>
                <mu>1</mu>
                <mu2>1</mu2>
              </ode>
              <torsional>
                <ode/>
              </torsional>
            </friction>
            <bounce/>
          </surface>
          <max_contacts>10</max_contacts>
        </collision>
        <visual name='hand_r_spring_proximal_link_visual'>
          <pose frame=''>0 0 0 0 -0 0</pose>
          <geometry>
            <mesh>
              <scale>1 1 1</scale>
              <uri>/opt/ros/melodic/share/hsrb_description/meshes/hand_v0/r_proximal.dae</uri>
            </mesh>
          </geometry>
          <material>
            <script>
              <uri>__default__</uri>
              <name>__default__</name>
            </script>
          </material>
        </visual>
        <gravity>1</gravity>
        <velocity_decay/>
        <self_collide>0</self_collide>
        <gravity>1</gravity>
        <enable_wind>0</enable_wind>
        <kinematic>0</kinematic>
      </link>
      <joint name='hand_r_spring_proximal_joint' type='revolute'>
        <child>hand_r_spring_proximal_link</child>
        <parent>hand_r_proximal_link</parent>
        <axis>
          <xyz>1 0 0</xyz>
          <limit>
            <lower>0</lower>
            <upper>0.698</upper>
            <effort>10</effort>
            <velocity>1</velocity>
          </limit>
          <dynamics>
            <damping>0.0001</damping>
            <friction>0</friction>
            <spring_reference>0</spring_reference>
            <spring_stiffness>0</spring_stiffness>
          </dynamics>
          <use_parent_model_frame>1</use_parent_model_frame>
        </axis>
        <physics>
          <ode>
            <limit>
              <cfm>0</cfm>
              <erp>0.2</erp>
            </limit>
          </ode>
        </physics>
      </joint>
      <link name='hand_r_mimic_distal_link'>
        <pose frame=''>0.17475 0.0535 0.878 0 -0 -3.14159</pose>
        <inertial>
          <pose frame=''>0 0 0 0 -0 0</pose>
          <mass>0.01</mass>
          <inertia>
            <ixx>0.0015</ixx>
            <ixy>0</ixy>
            <ixz>0</ixz>
            <iyy>0.0015</iyy>
            <iyz>0</iyz>
            <izz>0.0015</izz>
          </inertia>
        </inertial>
        <gravity>1</gravity>
        <velocity_decay/>
        <self_collide>0</self_collide>
        <gravity>1</gravity>
        <enable_wind>0</enable_wind>
        <kinematic>0</kinematic>
      </link>
      <joint name='hand_r_mimic_distal_joint' type='revolute'>
        <child>hand_r_mimic_distal_link</child>
        <parent>hand_r_spring_proximal_link</parent>
        <axis>
          <xyz>1 0 0</xyz>
          <limit>
            <lower>-0.698</lower>
            <upper>-0</upper>
            <effort>100</effort>
            <velocity>1</velocity>
          </limit>
          <dynamics>
            <damping>0.0001</damping>
            <friction>0</friction>
            <spring_reference>0</spring_reference>
            <spring_stiffness>0</spring_stiffness>
          </dynamics>
          <use_parent_model_frame>1</use_parent_model_frame>
        </axis>
        <physics>
          <ode>
            <limit>
              <cfm>0</cfm>
              <erp>0.2</erp>
            </limit>
          </ode>
        </physics>
      </joint>
      <link name='hand_r_distal_link'>
        <pose frame=''>0.17475 0.0535 0.878 0 -0 -3.14159</pose>
        <inertial>
          <pose frame=''>0.015062 -0.011661 0.024418 0 -0 0</pose>
          <mass>0.030927</mass>
          <inertia>
            <ixx>0.00150884</ixx>
            <ixy>1.24771e-07</ixy>
            <ixz>-4.51213e-07</ixz>
            <iyy>0.00150916</iyy>
            <iyz>2.75163e-06</iyz>
            <izz>0.00150357</izz>
          </inertia>
        </inertial>
        <collision name='hand_r_distal_link_collision'>
          <pose frame=''>0 0 0 0 -0 0</pose>
          <geometry>
            <mesh>
              <scale>1 1 1</scale>
              <uri>/opt/ros/melodic/share/hsrb_description/meshes/hand_v0/r_distal.stl</uri>
            </mesh>
          </geometry>
          <surface>
            <contact>
              <ode/>
            </contact>
            <friction>
              <ode>
                <mu>1</mu>
                <mu2>1</mu2>
              </ode>
              <torsional>
                <ode/>
              </torsional>
            </friction>
            <bounce/>
          </surface>
          <max_contacts>10</max_contacts>
        </collision>
        <visual name='hand_r_distal_link_visual'>
          <pose frame=''>0 0 0 0 -0 0</pose>
          <geometry>
            <mesh>
              <scale>1 1 1</scale>
              <uri>/opt/ros/melodic/share/hsrb_description/meshes/hand_v0/r_distal.dae</uri>
            </mesh>
          </geometry>
          <material>
            <script>
              <uri>__default__</uri>
              <name>__default__</name>
            </script>
          </material>
        </visual>
        <velocity_decay/>
        <gravity>0</gravity>
        <gravity>1</gravity>
        <velocity_decay/>
        <self_collide>0</self_collide>
        <gravity>0</gravity>
        <enable_wind>0</enable_wind>
        <kinematic>0</kinematic>
      </link>
      <joint name='hand_r_distal_joint' type='revolute'>
        <child>hand_r_distal_link</child>
        <parent>hand_r_mimic_distal_link</parent>
        <axis>
          <xyz>1 0 0</xyz>
          <limit>
            <lower>-1.24</lower>
            <upper>0.798</upper>
            <effort>100</effort>
            <velocity>1</velocity>
          </limit>
          <dynamics>
            <damping>0.0001</damping>
            <friction>0</friction>
            <spring_reference>0</spring_reference>
            <spring_stiffness>0</spring_stiffness>
          </dynamics>
          <use_parent_model_frame>1</use_parent_model_frame>
        </axis>
        <physics>
          <ode>
            <limit>
              <cfm>0</cfm>
              <erp>0.2</erp>
            </limit>
          </ode>
        </physics>
      </joint>
      <link name='base_b_bumper_link'>
        <pose frame=''>0 0.0013 0 0 -0 -3.14159</pose>
        <inertial>
          <pose frame=''>0 0 0 0 -0 0</pose>
          <mass>0.06</mass>
          <inertia>
            <ixx>0.001437</ixx>
            <ixy>0</ixy>
            <ixz>0</ixz>
            <iyy>0.001437</iyy>
            <iyz>0</iyz>
            <izz>0.002875</izz>
          </inertia>
        </inertial>
        <collision name='base_b_bumper_link_collision'>
          <pose frame=''>0 0 0 0 -0 0</pose>
          <geometry>
            <mesh>
              <scale>1 1 1</scale>
              <uri>/opt/ros/melodic/share/hsrb_description/meshes/base_v2/bumper.stl</uri>
            </mesh>
          </geometry>
          <surface>
            <contact>
              <ode/>
            </contact>
            <friction>
              <ode>
                <mu>0.9</mu>
                <mu2>0.9</mu2>
              </ode>
              <torsional>
                <ode/>
              </torsional>
            </friction>
            <bounce/>
          </surface>
          <max_contacts>10</max_contacts>
        </collision>
        <visual name='base_b_bumper_link_visual'>
          <pose frame=''>0 0 0 0 -0 0</pose>
          <geometry>
            <mesh>
              <scale>1 1 1</scale>
              <uri>/opt/ros/melodic/share/hsrb_description/meshes/base_v2/bumper.dae</uri>
            </mesh>
          </geometry>
          <material>
            <script>
              <uri>__default__</uri>
              <name>__default__</name>
            </script>
          </material>
        </visual>
        <gravity>1</gravity>
        <velocity_decay/>
        <self_collide>0</self_collide>
        <gravity>1</gravity>
        <sensor name='base_b_bumper_contact' type='contact'>
          <always_on>1</always_on>
          <update_rate>10</update_rate>
          <contact>
            <collision>base_b_bumper_link_collision</collision>
            <topic>__default_topic__</topic>
          </contact>
          <plugin name='hsrb_gazebo_ros_bumper_controller' filename='libhsrb_gazebo_ros_bumper.so'>
            <robotNamespace>/hsrb</robotNamespace>
            <bumperTopicName>base_b_bumper_sensor</bumperTopicName>
            <frameName>base_b_bumper_link</frameName>
          </plugin>
        </sensor>
        <enable_wind>0</enable_wind>
        <kinematic>0</kinematic>
      </link>
      <joint name='base_b_bumper_joint' type='revolute'>
        <child>base_b_bumper_link</child>
        <parent>base_footprint</parent>
        <axis>
          <xyz>-1 -0 0</xyz>
          <limit>
            <lower>0</lower>
            <upper>0</upper>
            <effort>0</effort>
            <velocity>0</velocity>
          </limit>
          <dynamics>
            <spring_reference>0</spring_reference>
            <spring_stiffness>0</spring_stiffness>
          </dynamics>
          <use_parent_model_frame>1</use_parent_model_frame>
        </axis>
      </joint>
      <link name='base_f_bumper_link'>
        <pose frame=''>0 0 0 0 -0 0</pose>
        <inertial>
          <pose frame=''>0 0 0 0 -0 0</pose>
          <mass>0.06</mass>
          <inertia>
            <ixx>0.001437</ixx>
            <ixy>0</ixy>
            <ixz>0</ixz>
            <iyy>0.001437</iyy>
            <iyz>0</iyz>
            <izz>0.002875</izz>
          </inertia>
        </inertial>
        <collision name='base_f_bumper_link_collision'>
          <pose frame=''>0 0 0 0 -0 0</pose>
          <geometry>
            <mesh>
              <scale>1 1 1</scale>
              <uri>/opt/ros/melodic/share/hsrb_description/meshes/base_v2/bumper.stl</uri>
            </mesh>
          </geometry>
          <surface>
            <contact>
              <ode/>
            </contact>
            <friction>
              <ode>
                <mu>0.9</mu>
                <mu2>0.9</mu2>
              </ode>
              <torsional>
                <ode/>
              </torsional>
            </friction>
            <bounce/>
          </surface>
          <max_contacts>10</max_contacts>
        </collision>
        <visual name='base_f_bumper_link_visual'>
          <pose frame=''>0 0 0 0 -0 0</pose>
          <geometry>
            <mesh>
              <scale>1 1 1</scale>
              <uri>/opt/ros/melodic/share/hsrb_description/meshes/base_v2/bumper.dae</uri>
            </mesh>
          </geometry>
          <material>
            <script>
              <uri>__default__</uri>
              <name>__default__</name>
            </script>
          </material>
        </visual>
        <gravity>1</gravity>
        <velocity_decay/>
        <self_collide>0</self_collide>
        <gravity>1</gravity>
        <sensor name='base_f_bumper_contact' type='contact'>
          <always_on>1</always_on>
          <update_rate>10</update_rate>
          <contact>
            <collision>base_f_bumper_link_collision</collision>
            <topic>__default_topic__</topic>
          </contact>
          <plugin name='hsrb_gazebo_ros_bumper_controller' filename='libhsrb_gazebo_ros_bumper.so'>
            <robotNamespace>/hsrb</robotNamespace>
            <bumperTopicName>base_f_bumper_sensor</bumperTopicName>
            <frameName>base_f_bumper_link</frameName>
          </plugin>
        </sensor>
        <enable_wind>0</enable_wind>
        <kinematic>0</kinematic>
      </link>
      <joint name='base_f_bumper_joint' type='revolute'>
        <child>base_f_bumper_link</child>
        <parent>base_footprint</parent>
        <axis>
          <xyz>1 0 0</xyz>
          <limit>
            <lower>0</lower>
            <upper>0</upper>
            <effort>0</effort>
            <velocity>0</velocity>
          </limit>
          <dynamics>
            <spring_reference>0</spring_reference>
            <spring_stiffness>0</spring_stiffness>
          </dynamics>
          <use_parent_model_frame>1</use_parent_model_frame>
        </axis>
      </joint>
      <link name='base_roll_link'>
        <pose frame=''>0 0 0 0 -0 0</pose>
        <inertial>
          <pose frame=''>-0.019482 0.002191 0.071013 0 -0 0</pose>
          <mass>10.2394</mass>
          <inertia>
            <ixx>0.07671</ixx>
            <ixy>-0.01005</ixy>
            <ixz>0.001749</ixz>
            <iyy>0.09057</iyy>
            <iyz>0.001549</iyz>
            <izz>0.145</izz>
          </inertia>
        </inertial>
        <gravity>1</gravity>
        <velocity_decay/>
        <self_collide>0</self_collide>
        <gravity>1</gravity>
        <enable_wind>0</enable_wind>
        <kinematic>0</kinematic>
      </link>
      <joint name='base_roll_joint' type='revolute'>
        <child>base_roll_link</child>
        <parent>base_footprint</parent>
        <axis>
          <xyz>0 0 1</xyz>
          <limit>
            <lower>-1e+16</lower>
            <upper>1e+16</upper>
          </limit>
          <dynamics>
            <damping>0.7</damping>
            <friction>0</friction>
            <spring_reference>0</spring_reference>
            <spring_stiffness>0</spring_stiffness>
          </dynamics>
          <use_parent_model_frame>1</use_parent_model_frame>
        </axis>
      </joint>
      <link name='base_l_drive_wheel_link'>
        <pose frame=''>-0.11 0.133 0.04 0 -0 0</pose>
        <inertial>
          <pose frame=''>0 0 0 0 -0 0</pose>
          <mass>0.2</mass>
          <inertia>
            <ixx>0.015</ixx>
            <ixy>0</ixy>
            <ixz>0</ixz>
            <iyy>0.015</iyy>
            <iyz>0</iyz>
            <izz>0.015</izz>
          </inertia>
        </inertial>
        <collision name='base_l_drive_wheel_link_collision'>
          <pose frame=''>0 0 0 1.5708 -0 0</pose>
          <geometry>
            <cylinder>
              <length>0.03</length>
              <radius>0.04</radius>
            </cylinder>
          </geometry>
          <surface>
            <contact>
              <ode>
                <kp>1e+06</kp>
                <kd>10</kd>
                <max_vel>1</max_vel>
                <min_depth>0</min_depth>
              </ode>
            </contact>
            <friction>
              <ode>
                <mu>1</mu>
                <mu2>1</mu2>
              </ode>
              <torsional>
                <ode/>
              </torsional>
            </friction>
            <bounce/>
          </surface>
          <max_contacts>10</max_contacts>
        </collision>
        <visual name='base_l_drive_wheel_link_visual'>
          <pose frame=''>0 0 0 1.5708 -0 0</pose>
          <geometry>
            <cylinder>
              <length>0.03</length>
              <radius>0.04</radius>
            </cylinder>
          </geometry>
          <material>
            <script>
              <name>Gazebo/FlatBlack</name>
              <uri>file://media/materials/scripts/gazebo.material</uri>
            </script>
          </material>
        </visual>
        <gravity>1</gravity>
        <velocity_decay/>
        <self_collide>0</self_collide>
        <gravity>1</gravity>
        <enable_wind>0</enable_wind>
        <kinematic>0</kinematic>
      </link>
      <joint name='base_l_drive_wheel_joint' type='revolute'>
        <child>base_l_drive_wheel_link</child>
        <parent>base_roll_link</parent>
        <axis>
          <xyz>0 1 0</xyz>
          <limit>
            <lower>-1e+16</lower>
            <upper>1e+16</upper>
          </limit>
          <dynamics>
            <damping>1</damping>
            <friction>0</friction>
            <spring_reference>0</spring_reference>
            <spring_stiffness>0</spring_stiffness>
          </dynamics>
          <use_parent_model_frame>1</use_parent_model_frame>
        </axis>
      </joint>
      <link name='base_l_passive_wheel_x_frame'>
        <pose frame=''>0.1495 0.055 0.03 0 -0 0</pose>
        <inertial>
          <pose frame=''>0 0 0 0 -0 0</pose>
          <mass>0.2</mass>
          <inertia>
            <ixx>0.015</ixx>
            <ixy>0</ixy>
            <ixz>0</ixz>
            <iyy>0.015</iyy>
            <iyz>0</iyz>
            <izz>0.015</izz>
          </inertia>
        </inertial>
        <self_collide>0</self_collide>
        <enable_wind>0</enable_wind>
        <kinematic>0</kinematic>
      </link>
      <joint name='base_l_passive_wheel_x_frame_joint' type='revolute'>
        <child>base_l_passive_wheel_x_frame</child>
        <parent>base_roll_link</parent>
        <axis>
          <xyz>1 0 0</xyz>
          <limit>
            <lower>-1e+16</lower>
            <upper>1e+16</upper>
          </limit>
          <dynamics>
            <damping>1</damping>
            <friction>0</friction>
            <spring_reference>0</spring_reference>
            <spring_stiffness>0</spring_stiffness>
          </dynamics>
          <use_parent_model_frame>1</use_parent_model_frame>
        </axis>
      </joint>
      <link name='base_l_passive_wheel_y_frame'>
        <pose frame=''>0.1495 0.055 0.03 0 -0 0</pose>
        <inertial>
          <pose frame=''>0 0 0 0 -0 0</pose>
          <mass>0.2</mass>
          <inertia>
            <ixx>0.015</ixx>
            <ixy>0</ixy>
            <ixz>0</ixz>
            <iyy>0.015</iyy>
            <iyz>0</iyz>
            <izz>0.015</izz>
          </inertia>
        </inertial>
        <self_collide>0</self_collide>
        <enable_wind>0</enable_wind>
        <kinematic>0</kinematic>
      </link>
      <joint name='base_l_passive_wheel_y_frame_joint' type='revolute'>
        <child>base_l_passive_wheel_y_frame</child>
        <parent>base_l_passive_wheel_x_frame</parent>
        <axis>
          <xyz>0 1 0</xyz>
          <limit>
            <lower>-1e+16</lower>
            <upper>1e+16</upper>
          </limit>
          <dynamics>
            <spring_reference>0</spring_reference>
            <spring_stiffness>0</spring_stiffness>
          </dynamics>
          <use_parent_model_frame>1</use_parent_model_frame>
        </axis>
      </joint>
      <link name='base_l_passive_wheel_z_link'>
        <pose frame=''>0.1495 0.055 0.03 0 -0 0</pose>
        <inertial>
          <pose frame=''>0 0 0 0 -0 0</pose>
          <mass>0.2</mass>
          <inertia>
            <ixx>0.015</ixx>
            <ixy>0</ixy>
            <ixz>0</ixz>
            <iyy>0.015</iyy>
            <iyz>0</iyz>
            <izz>0.015</izz>
          </inertia>
        </inertial>
        <collision name='base_l_passive_wheel_z_link_collision'>
          <pose frame=''>0 0 0 0 -0 0</pose>
          <geometry>
            <sphere>
              <radius>0.03</radius>
            </sphere>
          </geometry>
          <surface>
            <contact>
              <ode>
                <max_vel>1</max_vel>
              </ode>
            </contact>
            <friction>
              <ode>
                <mu>0.1</mu>
                <mu2>0.1</mu2>
              </ode>
              <torsional>
                <ode/>
              </torsional>
            </friction>
            <bounce/>
          </surface>
          <max_contacts>10</max_contacts>
        </collision>
        <visual name='base_l_passive_wheel_z_link_visual'>
          <pose frame=''>0 0 0 0 -0 0</pose>
          <geometry>
            <sphere>
              <radius>0.03</radius>
            </sphere>
          </geometry>
          <material>
            <script>
              <name>Gazebo/FlatBlack</name>
              <uri>file://media/materials/scripts/gazebo.material</uri>
            </script>
          </material>
        </visual>
        <gravity>1</gravity>
        <velocity_decay/>
        <self_collide>0</self_collide>
        <gravity>1</gravity>
        <enable_wind>0</enable_wind>
        <kinematic>0</kinematic>
      </link>
      <joint name='base_l_passive_wheel_z_joint' type='revolute'>
        <child>base_l_passive_wheel_z_link</child>
        <parent>base_l_passive_wheel_y_frame</parent>
        <axis>
          <xyz>0 0 1</xyz>
          <limit>
            <lower>-1e+16</lower>
            <upper>1e+16</upper>
          </limit>
          <dynamics>
            <spring_reference>0</spring_reference>
            <spring_stiffness>0</spring_stiffness>
          </dynamics>
          <use_parent_model_frame>1</use_parent_model_frame>
        </axis>
      </joint>
      <link name='base_r_drive_wheel_link'>
        <pose frame=''>-0.11 -0.133 0.04 0 -0 0</pose>
        <inertial>
          <pose frame=''>0 0 0 0 -0 0</pose>
          <mass>0.2</mass>
          <inertia>
            <ixx>0.015</ixx>
            <ixy>0</ixy>
            <ixz>0</ixz>
            <iyy>0.015</iyy>
            <iyz>0</iyz>
            <izz>0.015</izz>
          </inertia>
        </inertial>
        <collision name='base_r_drive_wheel_link_collision'>
          <pose frame=''>0 0 0 1.5708 -0 0</pose>
          <geometry>
            <cylinder>
              <length>0.03</length>
              <radius>0.04</radius>
            </cylinder>
          </geometry>
          <surface>
            <contact>
              <ode>
                <kp>1e+06</kp>
                <kd>10</kd>
                <max_vel>1</max_vel>
                <min_depth>0</min_depth>
              </ode>
            </contact>
            <friction>
              <ode>
                <mu>1</mu>
                <mu2>1</mu2>
              </ode>
              <torsional>
                <ode/>
              </torsional>
            </friction>
            <bounce/>
          </surface>
          <max_contacts>10</max_contacts>
        </collision>
        <visual name='base_r_drive_wheel_link_visual'>
          <pose frame=''>0 0 0 1.5708 -0 0</pose>
          <geometry>
            <cylinder>
              <length>0.03</length>
              <radius>0.04</radius>
            </cylinder>
          </geometry>
          <material>
            <script>
              <name>Gazebo/FlatBlack</name>
              <uri>file://media/materials/scripts/gazebo.material</uri>
            </script>
          </material>
        </visual>
        <gravity>1</gravity>
        <velocity_decay/>
        <self_collide>0</self_collide>
        <gravity>1</gravity>
        <enable_wind>0</enable_wind>
        <kinematic>0</kinematic>
      </link>
      <joint name='base_r_drive_wheel_joint' type='revolute'>
        <child>base_r_drive_wheel_link</child>
        <parent>base_roll_link</parent>
        <axis>
          <xyz>0 1 0</xyz>
          <limit>
            <lower>-1e+16</lower>
            <upper>1e+16</upper>
          </limit>
          <dynamics>
            <damping>1</damping>
            <friction>0</friction>
            <spring_reference>0</spring_reference>
            <spring_stiffness>0</spring_stiffness>
          </dynamics>
          <use_parent_model_frame>1</use_parent_model_frame>
        </axis>
      </joint>
      <link name='base_r_passive_wheel_x_frame'>
        <pose frame=''>0.1495 -0.055 0.03 0 -0 0</pose>
        <inertial>
          <pose frame=''>0 0 0 0 -0 0</pose>
          <mass>0.2</mass>
          <inertia>
            <ixx>0.015</ixx>
            <ixy>0</ixy>
            <ixz>0</ixz>
            <iyy>0.015</iyy>
            <iyz>0</iyz>
            <izz>0.015</izz>
          </inertia>
        </inertial>
        <self_collide>0</self_collide>
        <enable_wind>0</enable_wind>
        <kinematic>0</kinematic>
      </link>
      <joint name='base_r_passive_wheel_x_frame_joint' type='revolute'>
        <child>base_r_passive_wheel_x_frame</child>
        <parent>base_roll_link</parent>
        <axis>
          <xyz>1 0 0</xyz>
          <limit>
            <lower>-1e+16</lower>
            <upper>1e+16</upper>
          </limit>
          <dynamics>
            <damping>1</damping>
            <friction>0</friction>
            <spring_reference>0</spring_reference>
            <spring_stiffness>0</spring_stiffness>
          </dynamics>
          <use_parent_model_frame>1</use_parent_model_frame>
        </axis>
      </joint>
      <link name='base_r_passive_wheel_y_frame'>
        <pose frame=''>0.1495 -0.055 0.03 0 -0 0</pose>
        <inertial>
          <pose frame=''>0 0 0 0 -0 0</pose>
          <mass>0.2</mass>
          <inertia>
            <ixx>0.015</ixx>
            <ixy>0</ixy>
            <ixz>0</ixz>
            <iyy>0.015</iyy>
            <iyz>0</iyz>
            <izz>0.015</izz>
          </inertia>
        </inertial>
        <self_collide>0</self_collide>
        <enable_wind>0</enable_wind>
        <kinematic>0</kinematic>
      </link>
      <joint name='base_r_passive_wheel_y_frame_joint' type='revolute'>
        <child>base_r_passive_wheel_y_frame</child>
        <parent>base_r_passive_wheel_x_frame</parent>
        <axis>
          <xyz>0 1 0</xyz>
          <limit>
            <lower>-1e+16</lower>
            <upper>1e+16</upper>
          </limit>
          <dynamics>
            <spring_reference>0</spring_reference>
            <spring_stiffness>0</spring_stiffness>
          </dynamics>
          <use_parent_model_frame>1</use_parent_model_frame>
        </axis>
      </joint>
      <link name='base_r_passive_wheel_z_link'>
        <pose frame=''>0.1495 -0.055 0.03 0 -0 0</pose>
        <inertial>
          <pose frame=''>0 0 0 0 -0 0</pose>
          <mass>0.2</mass>
          <inertia>
            <ixx>0.015</ixx>
            <ixy>0</ixy>
            <ixz>0</ixz>
            <iyy>0.015</iyy>
            <iyz>0</iyz>
            <izz>0.015</izz>
          </inertia>
        </inertial>
        <collision name='base_r_passive_wheel_z_link_collision'>
          <pose frame=''>0 0 0 0 -0 0</pose>
          <geometry>
            <sphere>
              <radius>0.03</radius>
            </sphere>
          </geometry>
          <surface>
            <contact>
              <ode>
                <max_vel>1</max_vel>
              </ode>
            </contact>
            <friction>
              <ode>
                <mu>0.1</mu>
                <mu2>0.1</mu2>
              </ode>
              <torsional>
                <ode/>
              </torsional>
            </friction>
            <bounce/>
          </surface>
          <max_contacts>10</max_contacts>
        </collision>
        <visual name='base_r_passive_wheel_z_link_visual'>
          <pose frame=''>0 0 0 0 -0 0</pose>
          <geometry>
            <sphere>
              <radius>0.03</radius>
            </sphere>
          </geometry>
          <material>
            <script>
              <name>Gazebo/FlatBlack</name>
              <uri>file://media/materials/scripts/gazebo.material</uri>
            </script>
          </material>
        </visual>
        <gravity>1</gravity>
        <velocity_decay/>
        <self_collide>0</self_collide>
        <gravity>1</gravity>
        <enable_wind>0</enable_wind>
        <kinematic>0</kinematic>
      </link>
      <joint name='base_r_passive_wheel_z_joint' type='revolute'>
        <child>base_r_passive_wheel_z_link</child>
        <parent>base_r_passive_wheel_y_frame</parent>
        <axis>
          <xyz>0 0 1</xyz>
          <limit>
            <lower>-1e+16</lower>
            <upper>1e+16</upper>
          </limit>
          <dynamics>
            <spring_reference>0</spring_reference>
            <spring_stiffness>0</spring_stiffness>
          </dynamics>
          <use_parent_model_frame>1</use_parent_model_frame>
        </axis>
      </joint>
      <link name='torso_lift_link'>
        <pose frame=''>0 0 0.752 0 -0 0</pose>
        <inertial>
          <pose frame=''>-0.051142 0.003454 -0.2905 0 -0 0</pose>
          <mass>3.42078</mass>
          <inertia>
            <ixx>0.1045</ixx>
            <ixy>-0.000460885</ixy>
            <ixz>0.00010113</ixz>
            <iyy>0.105</iyy>
            <iyz>0.002941</iyz>
            <izz>0.01284</izz>
          </inertia>
        </inertial>
        <collision name='torso_lift_link_collision'>
          <pose frame=''>0 0 0 0 -0 0</pose>
          <geometry>
            <mesh>
              <scale>1 1 1</scale>
              <uri>/opt/ros/melodic/share/hsrb_description/meshes/torso_v0/torso.stl</uri>
            </mesh>
          </geometry>
          <surface>
            <contact>
              <ode/>
            </contact>
            <friction>
              <ode>
                <mu>0.9</mu>
                <mu2>0.9</mu2>
              </ode>
              <torsional>
                <ode/>
              </torsional>
            </friction>
            <bounce/>
          </surface>
          <max_contacts>10</max_contacts>
        </collision>
        <visual name='torso_lift_link_visual'>
          <pose frame=''>0 0 0 0 -0 0</pose>
          <geometry>
            <mesh>
              <scale>1 1 1</scale>
              <uri>/opt/ros/melodic/share/hsrb_description/meshes/torso_v0/torso_light.dae</uri>
            </mesh>
          </geometry>
          <material>
            <script>
              <uri>__default__</uri>
              <name>__default__</name>
            </script>
          </material>
        </visual>
        <gravity>1</gravity>
        <velocity_decay/>
        <self_collide>0</self_collide>
        <gravity>1</gravity>
        <enable_wind>0</enable_wind>
        <kinematic>0</kinematic>
      </link>
      <joint name='torso_lift_joint' type='prismatic'>
        <child>torso_lift_link</child>
        <parent>base_footprint</parent>
        <axis>
          <xyz>0 0 1</xyz>
          <limit>
            <lower>0</lower>
            <upper>0.345</upper>
            <effort>300</effort>
            <velocity>0.1</velocity>
          </limit>
          <dynamics>
            <damping>500</damping>
            <friction>0</friction>
            <spring_reference>0</spring_reference>
            <spring_stiffness>0</spring_stiffness>
          </dynamics>
          <use_parent_model_frame>1</use_parent_model_frame>
        </axis>
        <physics>
          <ode>
            <limit>
              <cfm>0</cfm>
              <erp>0.2</erp>
            </limit>
          </ode>
        </physics>
      </joint>
      <link name='head_pan_link'>
        <pose frame=''>0 0 0.752 0 -0 0</pose>
        <inertial>
          <pose frame=''>0.001724 -0.001969 -0.028886 0 -0 0</pose>
          <mass>0.571903</mass>
          <inertia>
            <ixx>0.000971142</ixx>
            <ixy>6.17949e-05</ixy>
            <ixz>-0.000113923</ixz>
            <iyy>0.000653355</iyy>
            <iyz>6.90363e-05</iyz>
            <izz>0.000765203</izz>
          </inertia>
        </inertial>
        <collision name='head_pan_link_collision'>
          <pose frame=''>0 0 0 0 -0 0</pose>
          <geometry>
            <mesh>
              <scale>1 1 1</scale>
              <uri>/opt/ros/melodic/share/hsrb_description/meshes/head_v1/head_pan.stl</uri>
            </mesh>
          </geometry>
          <surface>
            <contact>
              <ode/>
            </contact>
            <friction>
              <ode>
                <mu>0.9</mu>
                <mu2>0.9</mu2>
              </ode>
              <torsional>
                <ode/>
              </torsional>
            </friction>
            <bounce/>
          </surface>
          <max_contacts>10</max_contacts>
        </collision>
        <visual name='head_pan_link_visual'>
          <pose frame=''>0 0 0 0 -0 0</pose>
          <geometry>
            <mesh>
              <scale>1 1 1</scale>
              <uri>/opt/ros/melodic/share/hsrb_description/meshes/head_v1/head_pan.dae</uri>
            </mesh>
          </geometry>
          <material>
            <script>
              <uri>__default__</uri>
              <name>__default__</name>
            </script>
          </material>
        </visual>
        <gravity>1</gravity>
        <velocity_decay/>
        <self_collide>0</self_collide>
        <gravity>1</gravity>
        <enable_wind>0</enable_wind>
        <kinematic>0</kinematic>
      </link>
      <joint name='head_pan_joint' type='revolute'>
        <child>head_pan_link</child>
        <parent>torso_lift_link</parent>
        <axis>
          <xyz>0 0 1</xyz>
          <limit>
            <lower>-3.84</lower>
            <upper>1.75</upper>
            <effort>100</effort>
            <velocity>1</velocity>
          </limit>
          <dynamics>
            <damping>1</damping>
            <friction>0</friction>
            <spring_reference>0</spring_reference>
            <spring_stiffness>0</spring_stiffness>
          </dynamics>
          <use_parent_model_frame>1</use_parent_model_frame>
        </axis>
        <physics>
          <ode>
            <limit>
              <cfm>0</cfm>
              <erp>0.2</erp>
            </limit>
          </ode>
        </physics>
      </joint>
      <link name='head_tilt_link'>
        <pose frame=''>0.02 0 0.752 0 -0 0</pose>
        <inertial>
          <pose frame=''>-0.05355 -0.002148 0.117073 0 -0 0</pose>
          <mass>2.2038</mass>
          <inertia>
            <ixx>0.0280002</ixx>
            <ixy>-0.00013599</ixy>
            <ixz>0.00533594</ixz>
            <iyy>0.023706</iyy>
            <iyz>4.7745e-05</iyz>
            <izz>0.0202221</izz>
          </inertia>
        </inertial>
        <collision name='head_tilt_link_collision'>
          <pose frame=''>0 0 0 0 -0 0</pose>
          <geometry>
            <mesh>
              <scale>1 1 1</scale>
              <uri>/opt/ros/melodic/share/hsrb_description/meshes/head_v1/head.stl</uri>
            </mesh>
          </geometry>
          <surface>
            <contact>
              <ode/>
            </contact>
            <friction>
              <ode>
                <mu>0.9</mu>
                <mu2>0.9</mu2>
              </ode>
              <torsional>
                <ode/>
              </torsional>
            </friction>
            <bounce/>
          </surface>
          <max_contacts>10</max_contacts>
        </collision>
        <collision name='head_tilt_link_collision_1'>
          <pose frame=''>0 0 0 0 -0 0</pose>
          <geometry>
            <mesh>
              <scale>1 1 1</scale>
              <uri>/opt/ros/melodic/share/hsrb_description/meshes/head_v1/tablet.stl</uri>
            </mesh>
          </geometry>
          <surface>
            <contact>
              <ode/>
            </contact>
            <friction>
              <ode>
                <mu>0.9</mu>
                <mu2>0.9</mu2>
              </ode>
              <torsional>
                <ode/>
              </torsional>
            </friction>
            <bounce/>
          </surface>
          <max_contacts>10</max_contacts>
        </collision>
        <collision name='head_tilt_link_fixed_joint_lump__head_rgbd_sensor_link_collision_2'>
          <pose frame=''>-0.079796 0.022 0.215172 -1.5708 -0 -1.5708</pose>
          <geometry>
            <mesh>
              <scale>1 1 1</scale>
              <uri>/opt/ros/melodic/share/hsrb_parts_description/meshes/sensors/xtion.stl</uri>
            </mesh>
          </geometry>
          <surface>
            <contact>
              <ode/>
            </contact>
            <friction>
              <ode>
                <mu>0.9</mu>
                <mu2>0.9</mu2>
              </ode>
              <torsional>
                <ode/>
              </torsional>
            </friction>
            <bounce/>
          </surface>
          <max_contacts>10</max_contacts>
        </collision>
        <visual name='head_tilt_link_visual'>
          <pose frame=''>0 0 0 0 -0 0</pose>
          <geometry>
            <mesh>
              <scale>1 1 1</scale>
              <uri>/opt/ros/melodic/share/hsrb_description/meshes/head_v1/head_upper.dae</uri>
            </mesh>
          </geometry>
          <material>
            <script>
              <uri>__default__</uri>
              <name>__default__</name>
            </script>
          </material>
        </visual>
        <visual name='head_tilt_link_visual_1'>
          <pose frame=''>0 0 0 0 -0 0</pose>
          <geometry>
            <mesh>
              <scale>1 1 1</scale>
              <uri>/opt/ros/melodic/share/hsrb_description/meshes/head_v1/head_tilt.dae</uri>
            </mesh>
          </geometry>
          <material>
            <script>
              <uri>__default__</uri>
              <name>__default__</name>
            </script>
          </material>
        </visual>
        <visual name='head_tilt_link_visual_2'>
          <pose frame=''>0 0 0 0 -0 0</pose>
          <geometry>
            <mesh>
              <scale>1 1 1</scale>
              <uri>/opt/ros/melodic/share/hsrb_description/meshes/head_v1/tablet_base.dae</uri>
            </mesh>
          </geometry>
          <material>
            <script>
              <uri>__default__</uri>
              <name>__default__</name>
            </script>
          </material>
        </visual>
        <visual name='head_tilt_link_fixed_joint_lump__head_l_stereo_camera_link_visual_3'>
          <pose frame=''>0.02 0.07 0.061 -1.5708 -0 -1.5708</pose>
          <geometry>
            <mesh>
              <scale>1 1 1</scale>
              <uri>/opt/ros/melodic/share/hsrb_parts_description/meshes/sensors/head_camera.dae</uri>
            </mesh>
          </geometry>
          <material>
            <script>
              <uri>__default__</uri>
              <name>__default__</name>
            </script>
          </material>
        </visual>
        <visual name='head_tilt_link_fixed_joint_lump__head_r_stereo_camera_link_visual_4'>
          <pose frame=''>0.02 -0.07 0.061 -1.5708 -0 -1.5708</pose>
          <geometry>
            <mesh>
              <scale>1 1 1</scale>
              <uri>/opt/ros/melodic/share/hsrb_parts_description/meshes/sensors/head_camera.dae</uri>
            </mesh>
          </geometry>
          <material>
            <script>
              <uri>__default__</uri>
              <name>__default__</name>
            </script>
          </material>
        </visual>
        <visual name='head_tilt_link_fixed_joint_lump__head_rgbd_sensor_link_visual_5'>
          <pose frame=''>-0.079796 0.022 0.215172 -1.5708 -0 -1.5708</pose>
          <geometry>
            <mesh>
              <scale>1 1 1</scale>
              <uri>/opt/ros/melodic/share/hsrb_parts_description/meshes/sensors/xtion.dae</uri>
            </mesh>
          </geometry>
          <material>
            <script>
              <uri>__default__</uri>
              <name>__default__</name>
            </script>
          </material>
        </visual>
        <velocity_decay/>
        <velocity_decay/>
        <velocity_decay/>
        <sensor name='head_center_camera' type='camera'>
          <update_rate>10</update_rate>
          <camera name='head_center_camera'>
            <horizontal_fov>2</horizontal_fov>
            <image>
              <width>640</width>
              <height>480</height>
              <format>R8G8B8</format>
            </image>
            <clip>
              <near>0.01</near>
              <far>100</far>
            </clip>
            <noise>
              <type>gaussian</type>
              <mean>0</mean>
              <stddev>0.007</stddev>
            </noise>
          </camera>
          <plugin name='camera_controller' filename='libhsrb_gazebo_ros_camera.so'>
            <robotNamespace>/hsrb</robotNamespace>
            <alwaysOn>0</alwaysOn>
            <updateRate>0.0</updateRate>
            <cameraName>head_center_camera</cameraName>
            <imageTopicName>image_raw</imageTopicName>
            <cameraInfoTopicName>camera_info</cameraInfoTopicName>
            <frameName>head_center_camera_frame</frameName>
            <hackBaseline>0.07</hackBaseline>
            <distortionK1>0.0</distortionK1>
            <distortionK2>0.0</distortionK2>
            <distortionK3>0.0</distortionK3>
            <distortionT1>0.0</distortionT1>
            <distortionT2>0.0</distortionT2>
          </plugin>
          <pose frame=''>0.0195 0 0.061 0 -0 0</pose>
        </sensor>
        <velocity_decay/>
        <velocity_decay/>
        <sensor name='head_l_stereo_camera' type='camera'>
          <update_rate>4</update_rate>
          <camera name='head_l_stereo_camera'>
            <horizontal_fov>1.16763</horizontal_fov>
            <image>
              <width>1280</width>
              <height>960</height>
              <format>R8G8B8</format>
            </image>
            <clip>
              <near>0.05</near>
              <far>100</far>
            </clip>
            <noise>
              <type>gaussian</type>
              <mean>0</mean>
              <stddev>0.007</stddev>
            </noise>
          </camera>
          <plugin name='camera_controller' filename='libhsrb_gazebo_ros_camera.so'>
            <alwaysOn>0</alwaysOn>
            <updateRate>0.0</updateRate>
            <cameraName>head_l_stereo_camera</cameraName>
            <imageTopicName>image_rect_color</imageTopicName>
            <cameraInfoTopicName>camera_info</cameraInfoTopicName>
            <frameName>head_l_stereo_camera_frame</frameName>
            <robotNamespace>/hsrb</robotNamespace>
            <hackBaseline>0.0</hackBaseline>
            <distortionK1>0.0</distortionK1>
            <distortionK2>0.0</distortionK2>
            <distortionK3>0.0</distortionK3>
            <distortionT1>0.0</distortionT1>
            <distortionT2>0.0</distortionT2>
          </plugin>
          <pose frame=''>0.02 0.07 0.061 0 -0 0</pose>
        </sensor>
        <gravity>1</gravity>
        <velocity_decay/>
        <gravity>1</gravity>
        <gravity>1</gravity>
        <velocity_decay/>
        <sensor name='head_r_stereo_camera' type='camera'>
          <update_rate>4</update_rate>
          <camera name='head_r_stereo_camera'>
            <horizontal_fov>1.16763</horizontal_fov>
            <image>
              <width>1280</width>
              <height>960</height>
              <format>R8G8B8</format>
            </image>
            <clip>
              <near>0.05</near>
              <far>100</far>
            </clip>
            <noise>
              <type>gaussian</type>
              <mean>0</mean>
              <stddev>0.007</stddev>
            </noise>
          </camera>
          <plugin name='camera_controller' filename='libhsrb_gazebo_ros_camera.so'>
            <alwaysOn>0</alwaysOn>
            <updateRate>0.0</updateRate>
            <cameraName>head_r_stereo_camera</cameraName>
            <imageTopicName>image_rect_color</imageTopicName>
            <cameraInfoTopicName>camera_info</cameraInfoTopicName>
            <frameName>head_r_stereo_camera_frame</frameName>
            <robotNamespace>/hsrb</robotNamespace>
            <hackBaseline>0.14</hackBaseline>
            <distortionK1>0.0</distortionK1>
            <distortionK2>0.0</distortionK2>
            <distortionK3>0.0</distortionK3>
            <distortionT1>0.0</distortionT1>
            <distortionT2>0.0</distortionT2>
          </plugin>
          <pose frame=''>0.02 -0.07 0.061 0 -0 0</pose>
        </sensor>
        <gravity>1</gravity>
        <velocity_decay/>
        <self_collide>0</self_collide>
        <gravity>1</gravity>
        <gravity>1</gravity>
        <velocity_decay/>
        <sensor name='openni_camera_camera' type='depth'>
          <always_on>0</always_on>
          <update_rate>30</update_rate>
          <visualize>1</visualize>
          <camera name='__default__'>
            <horizontal_fov>1.047</horizontal_fov>
            <image>
              <width>640</width>
              <height>480</height>
              <format>B8G8R8</format>
            </image>
            <depth_camera>
              <output>depths</output>
            </depth_camera>
            <clip>
              <near>0.1</near>
              <far>100</far>
            </clip>
          </camera>
          <plugin name='head_rgbd_sensor_controller' filename='libhsrb_gazebo_ros_openni_kinect.so'>
            <alwaysOn>1</alwaysOn>
            <baseline>0.2</baseline>
            <updateRate>1.0</updateRate>
            <cameraName>head_rgbd_sensor</cameraName>
            <frameName>head_rgbd_sensor_rgb_frame</frameName>
            <robotNamespace>/hsrb</robotNamespace>
            <imageTopicName>//hsrb/head_rgbd_sensor/rgb/image_rect_color</imageTopicName>
            <cameraInfoTopicName>//hsrb/head_rgbd_sensor/rgb/camera_info</cameraInfoTopicName>
            <depthImageTopicName>//hsrb/head_rgbd_sensor/depth_registered/image_rect_raw</depthImageTopicName>
            <pointCloudTopicName>//hsrb/head_rgbd_sensor/depth_registered/rectified_points</pointCloudTopicName>
            <depthImageCameraInfoTopicName>//hsrb/head_rgbd_sensor/depth_registered/camera_info</depthImageCameraInfoTopicName>
            <pointCloudCutoff>0.5</pointCloudCutoff>
            <pointCloudCutoffMax>9.2</pointCloudCutoffMax>
            <distortionK1>0.0</distortionK1>
            <distortionK2>0.0</distortionK2>
            <distortionK3>0.0</distortionK3>
            <distortionT1>0.0</distortionT1>
            <distortionT2>0.0</distortionT2>
            <CxPrime>0.0</CxPrime>
            <Cx>0.0</Cx>
            <Cy>0.0</Cy>
            <focalLength>0.0</focalLength>
            <hackBaseline>0</hackBaseline>
            <encoding>16UC1</encoding>
          </plugin>
          <pose frame=''>-0.079796 0.022 0.215172 0 -0 0</pose>
        </sensor>
        <enable_wind>0</enable_wind>
        <kinematic>0</kinematic>
      </link>
      <joint name='head_tilt_joint' type='revolute'>
        <child>head_tilt_link</child>
        <parent>head_pan_link</parent>
        <axis>
          <xyz>0 -1 0</xyz>
          <limit>
            <lower>-1.57</lower>
            <upper>0.52</upper>
            <effort>100</effort>
            <velocity>1</velocity>
          </limit>
          <dynamics>
            <damping>10</damping>
            <friction>0</friction>
            <spring_reference>0</spring_reference>
            <spring_stiffness>0</spring_stiffness>
          </dynamics>
          <use_parent_model_frame>1</use_parent_model_frame>
        </axis>
        <physics>
          <ode>
            <limit>
              <cfm>0</cfm>
              <erp>0.2</erp>
            </limit>
          </ode>
        </physics>
      </joint>
      <plugin name='torso_mimic_plugin' filename='libtmc_gazebo_mimic_plugin.so'>
        <joint>torso_lift_joint</joint>
        <mimicJoint>arm_lift_joint</mimicJoint>
        <multiplier>0.5</multiplier>
        <robotNamespace>/</robotNamespace>
      </plugin>
      <plugin name='ft_sensor' filename='libgazebo_ros_ft_sensor.so'>
        <updateRate>30.0</updateRate>
        <topicName>hsrb/wrist_wrench/raw</topicName>
        <jointName>wrist_ft_sensor_frame_joint</jointName>
        <robotNamespace/>
      </plugin>
      <plugin name='hsrb_hrh_gripper_plugin' filename='libtmc_gazebo_hrh_gripper.so'>
        <sensitiveness>0.05</sensitiveness>
        <update_rate>1000.0</update_rate>
        <max_torque>8.0</max_torque>
        <error_tolerance>0.0872</error_tolerance>
        <stall_timeout>2.0</stall_timeout>
        <robot_namespace>/hsrb</robot_namespace>
        <robotNamespace>/</robotNamespace>
      </plugin>
      <plugin name='hsrb_grasp_hack_plugin' filename='libhsrb_grasp_hack.so'>
        <grasp_check>
          <attach_steps>1</attach_steps>
          <detach_steps>2</detach_steps>
          <min_contact_count>1</min_contact_count>
          <max_attach_weight>1.2</max_attach_weight>
        </grasp_check>
        <gripper_link>hand_r_distal_link</gripper_link>
        <gripper_link>hand_l_distal_link</gripper_link>
        <gripper_link>hand_r_spring_proximal_link</gripper_link>
        <gripper_link>hand_l_spring_proximal_link</gripper_link>
        <palm_link>wrist_ft_sensor_frame</palm_link>
        <robot_namespace>/hsrb</robot_namespace>
        <robotNamespace>/</robotNamespace>
      </plugin>
      <static>0</static>
      <plugin name='hsrb_ros_control' filename='libhsrb_gazebo_ros_control.so'>
        <robotNamespace>/hsrb</robotNamespace>
        <legacyModeNS>0</legacyModeNS>
      </plugin>
      <plugin name='hsrb_p3d_ground_truth' filename='libhsrb_gazebo_ros_p3d.so'>
        <robotNamespace>/hsrb</robotNamespace>
        <bodyName>base_footprint</bodyName>
        <topicName>odom_ground_truth</topicName>
        <frameName>map</frameName>
        <updateRate>30</updateRate>
        <xyzOffset>0.0 0.0 0.0</xyzOffset>
        <rpyOffset>0.0 0.0 0.0</rpyOffset>
      </plugin>
      <pose frame=''>1 1 0 0 -0 0.77</pose>
    </model>
    <model name='unit_box_1'>
      <pose frame=''>2.05665 -14.6706 0.5 0 -0 0</pose>
      <link name='link'>
        <inertial>
          <mass>1</mass>
          <inertia>
            <ixx>0.166667</ixx>
            <ixy>0</ixy>
            <ixz>0</ixz>
            <iyy>0.166667</iyy>
            <iyz>0</iyz>
            <izz>0.166667</izz>
          </inertia>
          <pose frame=''>0 0 0 0 -0 0</pose>
        </inertial>
        <collision name='collision'>
          <geometry>
            <box>
              <size>1 1 1</size>
            </box>
          </geometry>
          <max_contacts>10</max_contacts>
          <surface>
            <contact>
              <ode/>
            </contact>
            <bounce/>
            <friction>
              <torsional>
                <ode/>
              </torsional>
              <ode/>
            </friction>
          </surface>
        </collision>
        <visual name='visual'>
          <geometry>
            <box>
              <size>1 1 1</size>
            </box>
          </geometry>
          <material>
            <script>
              <name>Gazebo/Grey</name>
              <uri>file://media/materials/scripts/gazebo.material</uri>
            </script>
          </material>
        </visual>
        <self_collide>0</self_collide>
        <enable_wind>0</enable_wind>
        <kinematic>0</kinematic>
      </link>
    </model>
  </world>
</sdf>
